Workbook

Sheet B1_Dữ liệu đầu vào
A1: BƯỚC 1 – BẢNG DỮ LIỆU ĐẦU VÀO GIAI ĐOẠN 3
A4: A. Product Catalog (nguồn: Giai đoạn 0 – Bảng 1, Bảng 2 và mục 4.5; giá là mức dự kiến)
A5: Mã | B5: Sản phẩm | C5: Giá vốn (VND) | D5: Giá bán (VND) | E5: Margin | F5: Ghi chú
A6: BT500 | B6: Bình giữ nhiệt 500ml (mọi màu) | C6: 95000 | D6: 199000 | E6: =(D6-C6)/D6 -> 0.52261307 | F6: Hero – 3 SKU màu
A7: BT750 | B7: Bình giữ nhiệt 750ml (mọi màu) | C7: 110000 | D7: 229000 | E7: =(D7-C7)/D7 -> 0.51965066 | F7: Hero – 4 SKU màu
A8: BT1000 | B8: Bình giữ nhiệt 1000ml (mọi màu) | C8: 130000 | D8: 269000 | E8: =(D8-C8)/D8 -> 0.51672862 | F8: Hero – 3 SKU màu
A9: CS01 | B9: Túi đựng bình giữ nhiệt | C9: 35000 | D9: 79000 | E9: =(D9-C9)/D9 -> 0.55696203 | F9: Cross-sell
A10: CS02 | B10: Cọ vệ sinh bình | C10: 15000 | D10: 39000 | E10: =(D10-C10)/D10 -> 0.61538462 | F10: Cross-sell
A11: CS03 | B11: Dây đeo bình | C11: 20000 | D11: 49000 | E11: =(D11-C11)/D11 -> 0.59183673 | F11: Cross-sell
A12: CS04 | B12: Nắp bình thay thế | C12: 25000 | D12: 59000 | E12: =(D12-C12)/D12 -> 0.57627119 | F12: Cross-sell
A13: CS05 | B13: Bộ vệ sinh bình | C13: 35000 | D13: 89000 | E13: =(D13-C13)/D13 -> 0.60674157 | F13: Cross-sell
A14: COMBO1 | B14: Combo 1: 500ml + Cọ vệ sinh | C14: =C6+C10 -> 110000 | D14: 229000 | E14: =(D14-C14)/D14 -> 0.51965066 | F14: Giá vốn = tổng giá vốn thành phần
A15: COMBO2 | B15: Combo 2: 750ml + Túi đựng | C15: =C7+C9 -> 145000 | D15: 289000 | E15: =(D15-C15)/D15 -> 0.4982699 | F15: Giá vốn = tổng giá vốn thành phần
A16: COMBO3 | B16: Combo 3: 750ml + Cọ + Túi | C16: =C7+C9+C10 -> 160000 | D16: 349000 | E16: =(D16-C16)/D16 -> 0.54154728 | F16: Giá vốn = tổng giá vốn thành phần
A17: COMBO4 | B17: Combo 4: 1000ml + Túi + Cọ | C17: =C8+C9+C10 -> 180000 | D17: 389000 | E17: =(D17-C17)/D17 -> 0.53727506 | F17: Giá vốn = tổng giá vốn thành phần
A19: B. Giả định và dữ liệu CPC
A20: Nhóm | B20: Chỉ số | C20: Giá trị | D20: Nguồn / Giả định | E20: Trạng thái
A21: Ngân sách | B21: Tổng ngân sách quảng cáo (VND/tháng) | C21: ='Ngân sách'!C4 -> 30000000 | D21: Giả định theo yêu cầu đề bài | E21: Giả định
A22: Chuyển đổi | B22: CR (Conversion Rate) | C22: 0.025 | D22: Giả định minh họa theo đề bài (2,5%) | E22: Giả định
A23: CPC | B23: CPC kịch bản thấp (VND) | C23: =CPC_Data!$O$8 -> 447 | D23: Keyword Planner – trung vị Bid thấp | E23: Đã kiểm tra
A24: CPC | B24: CPC kịch bản cơ sở (VND) | C24: =CPC_Data!$O$9 -> 1493.25 | D24: Keyword Planner – trung vị trung điểm Bid thấp/cao | E24: Đã kiểm tra
A25: CPC | B25: CPC kịch bản cao (VND) | C25: =CPC_Data!$O$10 -> 2491.5 | D25: Keyword Planner – trung vị Bid cao | E25: Đã kiểm tra
A26: Từ khóa | B26: Số từ khóa Commercial/Transactional dùng tính CPC | C26: =CPC_Data!$O$6 -> 164 | D26: Đã loại từ khóa in/khắc tên | E26: Đã kiểm tra
A27: Từ khóa | B27: Tổng lượt tìm/tháng của nhóm này | C27: =CPC_Data!$O$7 -> 109000 | D27: Keyword Planner (lượt tìm làm tròn theo nhóm) | E27: Đã kiểm tra

Sheet Ngân sách
A1: PHÂN BỔ NGÂN SÁCH QUẢNG CÁO
A2: Đây là đề xuất phân bổ dựa trên dữ liệu Giai đoạn 1 (Trends, Search Intent, Social Insight). Tổng ngân sách và tỷ lệ là GIẢ ĐỊNH (ô vàng) – nhóm cần xác nhận hoặc điều chỉnh. Chưa gồm chi phí KOC/Influencer (tổng hợp riêng ở Bước 8).
A4: Tổng ngân sách quảng cáo (VND/tháng) | C4: 30000000
A6: 1. Phân bổ theo kênh
A7: Kênh | B7: Tỷ lệ | C7: Ngân sách (VND/tháng) | D7: Vai trò | E7: Căn cứ
A8: Google Search Ads | B8: 0.5 | C8: =$C$4*B8 -> 15000000 | D8: Bắt người đang có ý định mua | E8: Có dữ liệu CPC; 318 Commercial + 27 Transactional trong bộ 500 từ khóa; nhu cầu ổn định quanh năm
A9: Facebook / Meta Ads | B9: 0.25 | C9: =$C$4*B9 -> 7500000 | D9: Remarketing, bài so sánh, chốt đơn qua Messenger | E9: Social Insight: Facebook hỗ trợ giải đáp và chuyển đổi; test TP.HCM trước
A10: TikTok Ads (boost video KOC) | B10: 0.2 | C10: =$C$4*B10 -> 6000000 | D10: Tạo nhận thức, đẩy video test/review | E10: Social Insight: TikTok là kênh ưu tiên; nhóm 18–30 tuổi cần nội dung chứng minh
A11: Dự phòng / tối ưu | B11: 0.05 | C11: =$C$4*B11 -> 1500000 | D11: Tăng ngân sách cho kênh hiệu quả nhất | E11: Dữ liệu CPC/CR thực tế chưa có, cần buffer để điều chỉnh
A12: TỔNG | B12: =SUM(B8:B11) -> 1 | C12: =SUM(C8:C11) -> 30000000
A15: 2. Chia ngân sách Google Search theo nhóm từ khóa (theo tỷ trọng lượt tìm của từ khóa Commercial/Transactional)
A16: Nhóm từ khóa | B16: Số từ khóa | C16: Lượt tìm/tháng | D16: Tỷ trọng | E16: Ngân sách (VND/tháng)
A17: Nhu cầu chung | B17: =SUMIFS(CPC_Data!$I$6:$I$172,CPC_Data!$D$6:$D$172,A17) -> 70 | C17: =SUMPRODUCT((CPC_Data!$D$6:$D$172=A17)*CPC_Data!$E$6:$E$172*CPC_Data!$I$6:$I$172) -> 76850 | D17: =C17/$C$25 -> 0.70504587 | E17: =$C$8*D17 -> 10575688
A18: Dung tích | B18: =SUMIFS(CPC_Data!$I$6:$I$172,CPC_Data!$D$6:$D$172,A18) -> 49 | C18: =SUMPRODUCT((CPC_Data!$D$6:$D$172=A18)*CPC_Data!$E$6:$E$172*CPC_Data!$I$6:$I$172) -> 10100 | D18: =C18/$C$25 -> 0.09266055 | E18: =$C$8*D18 -> 1389908.3
A19: Thiết kế / Phong cách | B19: =SUMIFS(CPC_Data!$I$6:$I$172,CPC_Data!$D$6:$D$172,A19) -> 11 | C19: =SUMPRODUCT((CPC_Data!$D$6:$D$172=A19)*CPC_Data!$E$6:$E$172*CPC_Data!$I$6:$I$172) -> 9550 | D19: =C19/$C$25 -> 0.087614679 | E19: =$C$8*D19 -> 1314220.2
A20: Mua hàng / Giá | B20: =SUMIFS(CPC_Data!$I$6:$I$172,CPC_Data!$D$6:$D$172,A20) -> 10 | C20: =SUMPRODUCT((CPC_Data!$D$6:$D$172=A20)*CPC_Data!$E$6:$E$172*CPC_Data!$I$6:$I$172) -> 2750 | D20: =C20/$C$25 -> 0.025229358 | E20: =$C$8*D20 -> 378440.37
A21: Tính năng | B21: =SUMIFS(CPC_Data!$I$6:$I$172,CPC_Data!$D$6:$D$172,A21) -> 9 | C21: =SUMPRODUCT((CPC_Data!$D$6:$D$172=A21)*CPC_Data!$E$6:$E$172*CPC_Data!$I$6:$I$172) -> 2700 | D21: =C21/$C$25 -> 0.024770642 | E21: =$C$8*D21 -> 371559.63
A22: Chất liệu | B22: =SUMIFS(CPC_Data!$I$6:$I$172,CPC_Data!$D$6:$D$172,A22) -> 8 | C22: =SUMPRODUCT((CPC_Data!$D$6:$D$172=A22)*CPC_Data!$E$6:$E$172*CPC_Data!$I$6:$I$172) -> 3550 | D22: =C22/$C$25 -> 0.032568807 | E22: =$C$8*D22 -> 488532.11
A23: Thương hiệu | B23: =SUMIFS(CPC_Data!$I$6:$I$172,CPC_Data!$D$6:$D$172,A23) -> 4 | C23: =SUMPRODUCT((CPC_Data!$D$6:$D$172=A23)*CPC_Data!$E$6:$E$172*CPC_Data!$I$6:$I$172) -> 2000 | D23: =C23/$C$25 -> 0.018348624 | E23: =$C$8*D23 -> 275229.36
A24: Đối tượng sử dụng | B24: =SUMIFS(CPC_Data!$I$6:$I$172,CPC_Data!$D$6:$D$172,A24) -> 3 | C24: =SUMPRODUCT((CPC_Data!$D$6:$D$172=A24)*CPC_Data!$E$6:$E$172*CPC_Data!$I$6:$I$172) -> 1500 | D24: =C24/$C$25 -> 0.013761468 | E24: =$C$8*D24 -> 206422.02
A25: TỔNG | B25: =SUM(B17:B24) -> 164 | C25: =SUM(C17:C24) -> 109000 | D25: =SUM(D17:D24) -> 1 | E25: =SUM(E17:E24) -> 15000000
A27: Lưu ý: nhóm "Nhu cầu chung" chiếm tỷ trọng lớn vì có từ khóa rất rộng như "bình giữ nhiệt" (50.000 lượt/tháng) – nên dồn ngân sách vào các từ khóa dung tích, chất liệu, mua hàng/giá có ý định rõ hơn.
A28: Với Meta và TikTok chưa có dữ liệu CPC từ Keyword Planner; số click của hai kênh này cần giả định riêng ở Bước 4.

Sheet B2_AOV
A1: BƯỚC 2 – TÍNH AOV (Average Order Value)
A2: Công thức: AOV = Tổng doanh thu / Tổng số đơn hàng. Giá bán và giá vốn lấy từ Product Catalog (sheet B1). Cơ cấu đơn hàng (ô vàng) là GIẢ ĐỊNH trên 100 đơn vì chưa có dữ liệu bán thật – 3 kịch bản để thấy AOV thay đổi theo tỷ lệ bán combo.
A4: Sản phẩm / Combo | B4: Giá bán (VND) | C4: Giá vốn (VND) | D4: KB1: ít combo (số đơn) | E4: KB2: cơ sở (số đơn) | F4: KB3: nhiều combo (số đơn)
A5: Bình 500ml | B5: ='B1_Dữ liệu đầu vào'!D6 -> 199000 | C5: ='B1_Dữ liệu đầu vào'!C6 -> 95000 | D5: 30 | E5: 20 | F5: 10
A6: Bình 750ml | B6: ='B1_Dữ liệu đầu vào'!D7 -> 229000 | C6: ='B1_Dữ liệu đầu vào'!C7 -> 110000 | D6: 30 | E6: 25 | F6: 15
A7: Bình 1000ml | B7: ='B1_Dữ liệu đầu vào'!D8 -> 269000 | C7: ='B1_Dữ liệu đầu vào'!C8 -> 130000 | D7: 15 | E7: 10 | F7: 5
A8: Combo 1 (500ml + Cọ) | B8: ='B1_Dữ liệu đầu vào'!D14 -> 229000 | C8: ='B1_Dữ liệu đầu vào'!C14 -> 110000 | D8: 8 | E8: 10 | F8: 12
A9: Combo 2 (750ml + Túi) | B9: ='B1_Dữ liệu đầu vào'!D15 -> 289000 | C9: ='B1_Dữ liệu đầu vào'!C15 -> 145000 | D9: 8 | E9: 15 | F9: 20
A10: Combo 3 (750ml + Cọ + Túi) | B10: ='B1_Dữ liệu đầu vào'!D16 -> 349000 | C10: ='B1_Dữ liệu đầu vào'!C16 -> 160000 | D10: 5 | E10: 12 | F10: 23
A11: Combo 4 (1000ml + Túi + Cọ) | B11: ='B1_Dữ liệu đầu vào'!D17 -> 389000 | C11: ='B1_Dữ liệu đầu vào'!C17 -> 180000 | D11: 4 | E11: 8 | F11: 15
A12: Tổng số đơn | D12: =SUM(D5:D11) -> 100 | E12: =SUM(E5:E11) -> 100 | F12: =SUM(F5:F11) -> 100
A14: Tổng doanh thu (VND) | D14: =SUMPRODUCT($B$5:$B$11,D5:D11) -> 24320000 | E14: =SUMPRODUCT($B$5:$B$11,E5:E11) -> 26320000 | F14: =SUMPRODUCT($B$5:$B$11,F5:F11) -> 29160000
A15: Tổng giá vốn (VND) | D15: =SUMPRODUCT($C$5:$C$11,D5:D11) -> 11660000 | E15: =SUMPRODUCT($C$5:$C$11,E5:E11) -> 12585000 | F15: =SUMPRODUCT($C$5:$C$11,F5:F11) -> 13850000
A16: AOV (VND) = Doanh thu / Số đơn | D16: =IF(D12=0,0,D14/D12) -> 243200 | E16: =IF(E12=0,0,E14/E12) -> 263200 | F16: =IF(F12=0,0,F14/F12) -> 291600
A17: Margin bình quân | D17: =IF(D14=0,0,(D14-D15)/D14) -> 0.52055921 | E17: =IF(E14=0,0,(E14-E15)/E14) -> 0.5218465 | F17: =IF(F14=0,0,(F14-F15)/F14) -> 0.52503429
A18: Lợi nhuận gộp / đơn (VND) | D18: =D16*D17 -> 126600 | E18: =E16*E17 -> 137350 | F18: =F16*F17 -> 153100
A19: Kiểm tra: AOV trong khoảng giá bán | D19: =IF(AND(D16>=MIN($B$5:$B$11),D16<=MAX($B$5:$B$11)),"Hợp lý","Kiểm tra lại") -> Hợp lý | E19: =IF(AND(E16>=MIN($B$5:$B$11),E16<=MAX($B$5:$B$11)),"Hợp lý","Kiểm tra lại") -> Hợp lý | F19: =IF(AND(F16>=MIN($B$5:$B$11),F16<=MAX($B$5:$B$11)),"Hợp lý","Kiểm tra lại") -> Hợp lý
A21: Nhận xét (viết 2–3 câu):
A22: → AOV so với giá bình lẻ (199–269k); combo kéo AOV lên bao nhiêu; ưu tiên đẩy Combo nào; mức AOV và margin dùng cho Bước 6–7.
A23: Chưa gồm phụ kiện cross-sell mua lẻ (túi, cọ, dây đeo, nắp, bộ vệ sinh) – nếu nhóm giả định có bán lẻ, thêm dòng mới vào bảng.

Sheet CPC_Data
A1: Dữ liệu CPC – từ khóa Commercial + Transactional có dữ liệu bid
A2: Nguồn: Search_Intent_Result_SUA.xlsx (Google Keyword Planner, VN, 09/2025–08/2026). "Top of page bid" là mức giá thầu ước tính cho vị trí đầu trang (VND/click), KHÔNG phải CPC thực tế. Cột "Dùng" = 1 là từ khóa được đưa vào tính; 0 là loại (dịch vụ in/khắc tên, không phải mua bình).
A5: STT | B5: Keyword | C5: Search intent | D5: Topic group | E5: Lượt tìm/tháng | F5: Bid thấp (VND) | G5: Bid cao (VND) | H5: Bid trung điểm (VND) | I5: Dùng (1/0) | J5: Bid thấp (dùng) | K5: Bid cao (dùng) | L5: Trung điểm (dùng) | N5: Thống kê CPC (chỉ dòng Dùng = 1)
A6: 1 | B6: bình giữ nhiệt | C6: Commercial | D6: Nhu cầu chung | E6: 50000 | F6: 545 | G6: 12191 | H6: =AVERAGE(F6,G6) -> 6368 | I6: 1 | J6: =IF($I6=1,F6,"") -> 545 | K6: =IF($I6=1,G6,"") -> 12191 | L6: =IF($I6=1,H6,"") -> 6368 | N6: Số từ khóa dùng | O6: =SUM(I6:I172) -> 164
A7: 2 | B7: bình giữ nhiệt cao cấp | C7: Commercial | D7: Thiết kế / Phong cách | E7: 5000 | F7: 661 | G7: 2682 | H7: =AVERAGE(F7,G7) -> 1671.5 | I7: 1 | J7: =IF($I7=1,F7,"") -> 661 | K7: =IF($I7=1,G7,"") -> 2682 | L7: =IF($I7=1,H7,"") -> 1671.5 | N7: Tổng lượt tìm/tháng | O7: =SUMPRODUCT(E6:E172,I6:I172) -> 109000
A8: 3 | B8: bình nước giữ nhiệt | C8: Commercial | D8: Nhu cầu chung | E8: 5000 | F8: 448 | G8: 3982 | H8: =AVERAGE(F8,G8) -> 2215 | I8: 1 | J8: =IF($I8=1,F8,"") -> 448 | K8: =IF($I8=1,G8,"") -> 3982 | L8: =IF($I8=1,H8,"") -> 2215 | N8: Bid thấp – trung vị (VND) | O8: =MEDIAN(J6:J172) -> 447
A9: 4 | B9: binh giu nhiet | C9: Commercial | D9: Nhu cầu chung | E9: 500 | F9: 447 | G9: 2299 | H9: =AVERAGE(F9,G9) -> 1373 | I9: 1 | J9: =IF($I9=1,F9,"") -> 447 | K9: =IF($I9=1,G9,"") -> 2299 | L9: =IF($I9=1,H9,"") -> 1373 | N9: Trung điểm – trung vị (VND) | O9: =MEDIAN(L6:L172) -> 1493.25
A10: 5 | B10: binh giu nhiet starbuck | C10: Commercial | D10: Nhu cầu chung | E10: 500 | F10: 298 | G10: 2483 | H10: =AVERAGE(F10,G10) -> 1390.5 | I10: 1 | J10: =IF($I10=1,F10,"") -> 298 | K10: =IF($I10=1,G10,"") -> 2483 | L10: =IF($I10=1,H10,"") -> 1390.5 | N10: Bid cao – trung vị (VND) | O10: =MEDIAN(K6:K172) -> 2491.5
A11: 6 | B11: bình giữ nhiệt 1 lít | C11: Commercial | D11: Dung tích | E11: 500 | F11: 563 | G11: 1646 | H11: =AVERAGE(F11,G11) -> 1104.5 | I11: 1 | J11: =IF($I11=1,F11,"") -> 563 | K11: =IF($I11=1,G11,"") -> 1646 | L11: =IF($I11=1,H11,"") -> 1104.5 | N11: Trung điểm – trung bình (VND) | O11: =AVERAGE(L6:L172) -> 1665.4482
A12: 7 | B12: bình giữ nhiệt 1.5 lít | C12: Commercial | D12: Dung tích | E12: 500 | F12: 656 | G12: 2482 | H12: =AVERAGE(F12,G12) -> 1569 | I12: 1 | J12: =IF($I12=1,F12,"") -> 656 | K12: =IF($I12=1,G12,"") -> 2482 | L12: =IF($I12=1,H12,"") -> 1569 | N12: Trung điểm – bình quân gia quyền theo lượt tìm (VND) | O12: =SUMPRODUCT(H6:H172,E6:E172,I6:I172)/SUMPRODUCT(E6:E172,I6:I172) -> 3837.6399
A13: 8 | B13: bình giữ nhiệt 1000ml | C13: Commercial | D13: Dung tích | E13: 500 | F13: 448 | G13: 3438 | H13: =AVERAGE(F13,G13) -> 1943 | I13: 1 | J13: =IF($I13=1,F13,"") -> 448 | K13: =IF($I13=1,G13,"") -> 3438 | L13: =IF($I13=1,H13,"") -> 1943
A14: 9 | B14: bình giữ nhiệt 1500ml | C14: Commercial | D14: Dung tích | E14: 500 | F14: 691 | G14: 2478 | H14: =AVERAGE(F14,G14) -> 1584.5 | I14: 1 | J14: =IF($I14=1,F14,"") -> 691 | K14: =IF($I14=1,G14,"") -> 2478 | L14: =IF($I14=1,H14,"") -> 1584.5
A15: 10 | B15: bình giữ nhiệt 1l | C15: Commercial | D15: Dung tích | E15: 500 | F15: 447 | G15: 2444 | H15: =AVERAGE(F15,G15) -> 1445.5 | I15: 1 | J15: =IF($I15=1,F15,"") -> 447 | K15: =IF($I15=1,G15,"") -> 2444 | L15: =IF($I15=1,H15,"") -> 1445.5
A16: 11 | B16: bình giữ nhiệt 2 lít | C16: Commercial | D16: Dung tích | E16: 500 | F16: 618 | G16: 1643 | H16: =AVERAGE(F16,G16) -> 1130.5 | I16: 1 | J16: =IF($I16=1,F16,"") -> 618 | K16: =IF($I16=1,G16,"") -> 1643 | L16: =IF($I16=1,H16,"") -> 1130.5
A17: 12 | B17: bình giữ nhiệt 2l | C17: Commercial | D17: Dung tích | E17: 500 | F17: 447 | G17: 2491 | H17: =AVERAGE(F17,G17) -> 1469 | I17: 1 | J17: =IF($I17=1,F17,"") -> 447 | K17: =IF($I17=1,G17,"") -> 2491 | L17: =IF($I17=1,H17,"") -> 1469
A18: 13 | B18: bình giữ nhiệt 3 lít | C18: Commercial | D18: Dung tích | E18: 500 | F18: 447 | G18: 694 | H18: =AVERAGE(F18,G18) -> 570.5 | I18: 1 | J18: =IF($I18=1,F18,"") -> 447 | K18: =IF($I18=1,G18,"") -> 694 | L18: =IF($I18=1,H18,"") -> 570.5
A19: 14 | B19: bình giữ nhiệt 300ml | C19: Commercial | D19: Dung tích | E19: 500 | F19: 657 | G19: 2689 | H19: =AVERAGE(F19,G19) -> 1673 | I19: 1 | J19: =IF($I19=1,F19,"") -> 657 | K19: =IF($I19=1,G19,"") -> 2689 | L19: =IF($I19=1,H19,"") -> 1673
A20: 15 | B20: bình giữ nhiệt 304 | C20: Commercial | D20: Chất liệu | E20: 500 | F20: 358 | G20: 867 | H20: =AVERAGE(F20,G20) -> 612.5 | I20: 1 | J20: =IF($I20=1,F20,"") -> 358 | K20: =IF($I20=1,G20,"") -> 867 | L20: =IF($I20=1,H20,"") -> 612.5
A21: 16 | B21: bình giữ nhiệt 316 | C21: Commercial | D21: Chất liệu | E21: 500 | F21: 518 | G21: 2767 | H21: =AVERAGE(F21,G21) -> 1642.5 | I21: 1 | J21: =IF($I21=1,F21,"") -> 518 | K21: =IF($I21=1,G21,"") -> 2767 | L21: =IF($I21=1,H21,"") -> 1642.5
A22: 17 | B22: bình giữ nhiệt 5 lit | C22: Commercial | D22: Dung tích | E22: 500 | F22: 377 | G22: 2060 | H22: =AVERAGE(F22,G22) -> 1218.5 | I22: 1 | J22: =IF($I22=1,F22,"") -> 377 | K22: =IF($I22=1,G22,"") -> 2060 | L22: =IF($I22=1,H22,"") -> 1218.5
A23: 18 | B23: bình giữ nhiệt 500ml | C23: Commercial | D23: Dung tích | E23: 500 | F23: 448 | G23: 1643 | H23: =AVERAGE(F23,G23) -> 1045.5 | I23: 1 | J23: =IF($I23=1,F23,"") -> 448 | K23: =IF($I23=1,G23,"") -> 1643 | L23: =IF($I23=1,H23,"") -> 1045.5
A24: 19 | B24: bình giữ nhiệt cao cấp của mỹ | C24: Commercial | D24: Thiết kế / Phong cách | E24: 500 | F24: 377 | G24: 2684 | H24: =AVERAGE(F24,G24) -> 1530.5 | I24: 1 | J24: =IF($I24=1,F24,"") -> 377 | K24: =IF($I24=1,G24,"") -> 2684 | L24: =IF($I24=1,H24,"") -> 1530.5
... A172: 167 | B172: bình giữ nhiệt dễ thương | C172: Commercial | D172: Nhu cầu chung | E172: 50 | F172: 447 | G172: 4390 | H172: =AVERAGE(F172,G172) -> 2418.5 | I172: 1 | J172: =IF($I172=1,F172,"") -> 447 | K172: =IF($I172=1,G172,"") -> 4390 | L172: =IF($I172=1,H172,"") -> 2418.5

Sheet Bước 8 
A1: BƯỚC 8 – TỔNG HỢP CHI PHÍ SOCIAL / KOC
A2: Chú thích: Chữ xanh = số lấy từ Bước 1–6 / Product Catalog (không sửa). Ô VÀNG = GIẢ ĐỊNH ĐỀ XUẤT, chưa có dữ liệu thực tế, nhóm cần xác nhận hoặc điều chỉnh. Chữ đen = công thức, tự tính lại khi sửa ô vàng hoặc số đầu vào. Đơn vị: VND.
A5: A. Dữ liệu tham chiếu từ Bước 1–2 (sheet "Ngân sách" và Product Catalog)
A6: STT | B6: Chỉ số | E6: Giá trị (VND) | F6: Nguồn | G6: Trạng thái
A7: 1 | B7: Tổng ngân sách quảng cáo / tháng | E7: 30000000 | F7: Bước 1–2, sheet Ngân sách – giả định theo đề bài | G7: Giả định
A8: 2 | B8: Google Search Ads (50%) | E8: 15000000 | F8: Bước 1–2, sheet Ngân sách – không thuộc Social, ghi để đối chiếu | G8: Giả định
A9: 3 | B9: Facebook / Meta Ads (25%) | E9: 7500000 | F9: Bước 1–2, sheet Ngân sách | G9: Giả định
A10: 4 | B10: TikTok Ads – boost video KOC (20%) | E10: 6000000 | F10: Bước 1–2, sheet Ngân sách | G10: Giả định
A11: 5 | B11: Dự phòng / tối ưu quảng cáo (5%) | E11: 1500000 | F11: Bước 1–2, sheet Ngân sách | G11: Giả định
A12: 6 | B12: Giá vốn Bình giữ nhiệt 500ml (BT500) | E12: 95000 | F12: Bước 1, Product Catalog (mã BT500) | G12: Đã kiểm tra
B13: Kiểm tra: Google + Meta + TikTok + Dự phòng = Tổng ngân sách | E13: =IF(E8+E9+E10+E11=E7,"Khớp","Lệch") -> Khớp | F13: Phải hiện "Khớp" trước khi bàn giao
A15: B. Chi phí QUẢNG CÁO Social (trả cho nền tảng)
A16: STT | B16: Hạng mục | C16: Số lượng | D16: Đơn giá | E16: Thành tiền (VND/tháng) | F16: Nguồn / Giả định | G16: Trạng thái
A17: 1 | B17: Facebook / Meta Ads (remarketing, bài so sánh, chốt đơn Messenger) | E17: =$E$9 -> 7500000 | F17: Lấy từ Bước 1–2. Chưa có CPC Meta nên số click kênh này giả định riêng ở Bước 4. | G17: Giả định
A18: 2 | B18: TikTok Ads (boost video KOC/review) | E18: =$E$10 -> 6000000 | F18: Lấy từ Bước 1–2. Dùng để đẩy video của KOC ở mục C, tránh tính trùng với phí KOC. | G18: Giả định
B19: Tổng quảng cáo Social (B) | E19: =SUM(E17:E18) -> 13500000
A21: C. Chi phí KOC / INFLUENCER (trả cho người sáng tạo nội dung, KHÔNG phải phí nền tảng)
A22: STT | B22: Hạng mục | C22: Số lượng | D22: Đơn giá (VND) | E22: Thành tiền (VND) | F22: Nguồn / Giả định | G22: Trạng thái
A23: 1 | B23: Phí đăng video của KOC (micro-KOC, TikTok/Facebook) | C23: 8 | D23: 500000 | E23: =C23*D23 -> 4000000 | F23: GIẢ ĐỊNH đề xuất: 8 KOC × 1 video, 500.000đ/video. Chưa có báo giá thực, cần hỏi giá KOC hoặc nhóm thống nhất. | G23: Giả định
A24: 2 | B24: Sản phẩm seeding gửi KOC (Bình 500ml, tính theo giá vốn) | C24: =C23 -> 8 | D24: =$E$12 -> 95000 | E24: =C24*D24 -> 760000 | F24: Số lượng = số KOC ở dòng trên. Đơn giá = giá vốn BT500 trong Product Catalog (chi phí thật của nhóm, không phải giá bán). | G24: Đã kiểm tra
A25: 3 | B25: Phí vận chuyển sản phẩm seeding | C25: =C23 -> 8 | D25: 30000 | E25: =C25*D25 -> 240000 | F25: GIẢ ĐỊNH đề xuất: 30.000đ/đơn gửi. Cần đối chiếu biểu phí đơn vị vận chuyển. | G25: Giả định
B26: Tổng KOC / Influencer cố định (C) | E26: =SUM(E23:E25) -> 5000000
A28: D. Chi phí TRIỂN KHAI khác
A29: STT | B29: Hạng mục | C29: Số lượng | D29: Đơn giá (VND) | E29: Thành tiền (VND) | F29: Nguồn / Giả định | G29: Trạng thái
A30: 1 | B30: Sản xuất nội dung (quay, dựng video, ảnh sản phẩm) – gói tháng | C30: 1 | D30: 2000000 | E30: =C30*D30 -> 2000000 | F30: GIẢ ĐỊNH đề xuất: 2.000.000đ/tháng (nếu nhóm tự quay thì có thể giảm). Cần nhóm xác nhận. | G30: Giả định
B31: Tổng triển khai khác (D) | E31: =SUM(E30:E30) -> 2000000
A33: E. Dữ liệu tham chiếu từ Bước 2, 3, 4, 5, 6 (dùng để tính hoa hồng KOC và CPO)
A34: STT | B34: Chỉ số | E34: Giá trị | F34: Nguồn | G34: Trạng thái
A35: 1 | B35: AOV cơ sở – KB2 (VND/đơn) | E35: 259200 | F35: Bước 2, mục 2.3 (KB2 – cơ sở): 25.920.000 đ / 100 đơn. Cần dùng cùng bản giá combo đã chốt ở Bước 1 (xem ghi chú mục I). | G35: Đã kiểm tra
A36: 2 | B36: Lãi gộp bình quân/đơn – KB2 (VND/đơn) | E36: 133350 | F36: Bước 2, mục 2.3 (KB2): 13.335.000 đ / 100 đơn. Là lãi gộp trước chi phí quảng cáo, vận chuyển, phí nền tảng. | G36: Đã kiểm tra
A37: 3 | B37: CR – tỷ lệ chuyển đổi giả định | E37: 0.025 | F37: Bước 3 – giả định minh họa theo đề bài, chưa đo từ website thực tế. | G37: Giả định
A38: 4 | B38: Click TikTok/tháng – Phạm vi B, kịch bản Cơ sở | E38: 1500 | F38: Bước 4, mục 4.4: 6.000.000 / CPC tham chiếu 4.000 đ/click. | G38: Giả định
A39: 5 | B39: Tổng click/tháng – Phạm vi B (Google + Meta + TikTok), Cơ sở | E39: 14272 | F39: Bước 4, mục 4.4: ngân sách 28.500.000 đ; CPC Meta/TikTok là tham chiếu thị trường. | G39: Giả định
A40: 6 | B40: Số đơn dự báo/tháng – Phạm vi B, Cơ sở | E40: =ROUND(E39*E37,0) -> 357 | F40: Bước 5, mục 5.2: 14.272 × 2,5% = 356,8 → khoảng 357 đơn/tháng. | G40: Ước tính
A41: 7 | B41: Chi phí quảng cáo 3 kênh quy đổi thành click (Google + Meta + TikTok) | E41: =E8+E9+E10 -> 28500000 | F41: Bước 4/6: 28.500.000 đ, không gồm dự phòng 1.500.000 đ. | G41: Giả định
A42: 8 | B42: CPO quảng cáo Phạm vi B theo Bước 6 (VND/đơn) | E42: 79832 | F42: Bước 6, mục 6.2: 28.500.000 / 357 = 79.832 đ/đơn. | G42: Đã kiểm tra
B43: Kiểm tra: CPO tính lại ở đây = CPO Bước 6 | E43: =IF(ABS(E41/E40-E42)<1,"Khớp","Lệch") -> Khớp | F43: Phải hiện "Khớp" trước khi bàn giao
A45: F. Chi phí BIẾN ĐỔI – Hoa hồng KOC/affiliate (tính từ Số đơn ở Bước 5 và AOV ở Bước 2)
A46: STT | B46: Hạng mục | D46: Tỷ lệ | E46: Thành tiền / Số lượng | F46: Cách tính / Giả định | G46: Trạng thái
A47: 1 | B47: Tỷ lệ hoa hồng KOC/affiliate trên doanh thu đơn có mã KOC | D47: 0.1 | F47: GIẢ ĐỊNH đề xuất: 10% doanh thu đơn có mã KOC. Cần thay bằng mức thỏa thuận thực với KOC. | G47: Giả định
...
