Workbook

Sheet Huong_dan
A1: HƯỚNG DẪN SỬ DỤNG FILE GIAI ĐOẠN 5 – SOVA
A2: Mục | B2: Hướng dẫn
A3: Nguyên tắc dữ liệu | B3: Không được trình bày dữ liệu mô phỏng là số liệu thực tế. Sheet Traffic_Mo_phong được chuyển từ file người dùng cung cấp và gắn nhãn mô phỏng.
A4: Nhập SEM | B4: Khi có dữ liệu Google Ads thật/Preview, nhập vào Nhap_SEM. Nếu chỉ có Preview, chỉ ghi trạng thái/cấu hình; không bịa Impressions, Clicks, đơn hàng.
A5: Nhập Social | B5: Nhập từng bài/video ở Nhap_Social; phân biệt Organic/Paid. Chi phí boost chỉ ghi một lần ở Nhap_Social.
A6: Nhập KOC | B6: Danh sách 5 KOC hiện là đề xuất, chưa xác nhận hợp tác. Không điền views/reach/clicks/đơn nếu chưa có ảnh analytics hoặc hệ thống đơn.
A7: Nhập Traffic | B7: Nhap_Traffic hiện chứa ví dụ mô phỏng 14 ngày; thay bằng export GA4/Search Console/UTM thật khi có.
A8: Dashboard | B8: Dashboard_GD5 và Tong_hop_kenh là dashboard Excel/nguồn cấu trúc để nhập lên Google Sheets và kết nối Looker Studio. Chưa phải dashboard Looker Studio đã kết nối trực tuyến.
A9: CAC/ROAS | B9: Chỉ kết luận CAC/ROAS sau khi nhập chi phí, đơn hàng, doanh thu thực tế và điền mốc dự kiến từ GĐ3. Các ô trống không phải số 0 hiệu quả.
A10: Intent | B10: Nhap_Intent dùng dữ liệu bộ 500 keyword của GĐ4. Tỷ lệ theo keyword khác tỷ lệ theo lượt tìm kiếm; chọn rõ chỉ tiêu khi trình bày.
A11: Ngân sách | B11: Google 15.000.000/tháng, Meta 7.500.000/tháng, TikTok 6.000.000/tháng, dự phòng 1.500.000/tháng theo tài liệu GĐ5; đối chiếu file GĐ3 gốc trước khi nộp.
A12: Tên thương hiệu/SKU | B12: Tài liệu còn chỗ chưa thống nhất SOVA/Mie SOVA và giá Combo 3/4. Cần chốt trước khi đăng nội dung.
A13: Minh chứng cần lưu | B13: Ảnh Google Ads Preview/review; ảnh bài Fanpage/TikTok; ảnh Analytics; tin nhắn/brief KOC và xác nhận; export GA4/Ads; ảnh Looker Studio; bản chụp tình huống Pivot.

Sheet Dashboard_GD5
A1: SOVA | GIAI ĐOẠN 5 – OMNICHANNEL & BI
A2: Bản dashboard Excel mẫu; dữ liệu traffic 01–14/10/2026 là mô phỏng, không phải kết quả thực tế.
E3: Trạng thái dữ liệu
A4: Organic Sessions | B4: =SUMIFS(Nhap_Traffic!D2:D1000,Nhap_Traffic!C2:C1000,"Organic") -> 819 | C4: Sessions từ Organic Search (mô phỏng) | E4: Traffic: mô phỏng
A5: Paid Sessions | B5: =SUMIFS(Nhap_Traffic!D2:D1000,Nhap_Traffic!C2:C1000,"Paid") -> 603 | C5: Sessions từ quảng cáo trả phí (mô phỏng) | E5: SEM/Social/KOC: chờ dữ liệu thật
A6: Social Organic Sessions | B6: =SUMIFS(Nhap_Traffic!D2:D1000,Nhap_Traffic!C2:C1000,"Social Organic") -> 262 | C6: Sessions từ Social tự nhiên (mô phỏng) | E6: CAC/ROAS: chưa đủ dữ liệu để kết luận
A7: Tổng Sessions | B7: =SUM(B4:B6) -> 1684 | C7: Tổng sessions, không cộng clicks vào sessions
A8: Paid Spend | B8: =SUMIFS(Traffic_Mo_phong!I2:I1000,Traffic_Mo_phong!B2:B1000,"Paid") -> 2382000 | C8: Chi phí paid trong dữ liệu mô phỏng
A9: Paid Impressions | B9: =SUMIFS(Traffic_Mo_phong!G2:G1000,Traffic_Mo_phong!B2:B1000,"Paid") -> 27740 | C9: Lượt hiển thị paid
A10: Paid CPM | B10: =IF(B9=0,"",B8/B9*1000) -> 85868.782 | C10: Chi phí/1.000 impressions
A11: Intent Commercial – tỷ lệ keyword | B11: =Nhap_Intent!D2 -> 0.636 | C11: Lấy từ bộ 500 keyword GĐ4
A12: Intent Informational – tỷ lệ keyword | B12: =Nhap_Intent!D3 -> 0.042 | C12: Lấy từ bộ 500 keyword GĐ4
A13: Intent Navigational – tỷ lệ keyword | B13: =Nhap_Intent!D4 -> 0.268 | C13: Lấy từ bộ 500 keyword GĐ4
A14: Intent Transactional – tỷ lệ keyword | B14: =Nhap_Intent!D5 -> 0.054 | C14: Lấy từ bộ 500 keyword GĐ4
A15: Doanh thu ghi nhận | B15: =IF(SUM(Tong_hop_kenh!G2:G5)=0,"",SUM(Tong_hop_kenh!G2:G5)) -> #REF! | C15: Hiện chưa có doanh thu thực tế; sẽ là 0/trống cho đến khi nhập dữ liệu
A16: CAC tổng | B16: =IF(SUM(Tong_hop_kenh!F2:F5)=0,"",SUM(Tong_hop_kenh!B2:B5)/SUM(Tong_hop_kenh!F2:F5)) -> #REF! | C16: Chi phí / đơn hàng, chỉ có ý nghĩa khi nhập chi phí và đơn thật
A17: ROAS tổng | B17: =IF(OR(SUM(Tong_hop_kenh!B2:B5)=0,SUM(Tong_hop_kenh!G2:G5)=0),"",SUM(Tong_hop_kenh!G2:G5)/SUM(Tong_hop_kenh!B2:B5)) -> #REF! | C17: Doanh thu / chi phí; không diễn giải khi chưa có dữ liệu thực

Sheet Bang_chi_so
A1: STT | B1: Nhóm | C1: Chỉ số | D1: Định nghĩa | E1: Công thức | F1: Nguồn lấy dữ liệu | G1: Người cung cấp | H1: Sheet nhập | I1: Dùng ở bước (GĐ5) | J1: Biểu đồ gợi ý trên Looker Studio
A2: 1 | B2: Hiển thị | C2: Impressions | D2: Số lần quảng cáo hoặc nội dung được hiển thị | E2: Tổng từ báo cáo nền tảng | F2: Google Ads; Meta Insights; TikTok Analytics | G2: TV2 (SEM); TV4 (Social, KOC) | H2: Nhap_SEM; Nhap_Social; Nhap_KOC | I2: Bước 7 | J2: Cột theo kênh; đường theo ngày
A3: 2 | B3: Hiển thị | C3: Reach | D3: Số người duy nhất nhìn thấy nội dung (chỉ có ở Social và KOC) | E3: Tổng từ báo cáo nền tảng | F3: Meta Insights; TikTok Analytics; số liệu KOC cung cấp | G3: TV4 | H3: Nhap_Social; Nhap_KOC | I3: Bước 7 | J3: Cột theo kênh
A4: 3 | B4: Hiển thị | C4: CPM | D4: Chi phí cho 1.000 lượt hiển thị | E4: Chi phí ÷ Impressions × 1.000 | F4: Tính từ Chi phí và Impressions | G4: TV1 tổng hợp | H4: Tong_hop_kenh | I4: Bước 7 | J4: Bảng và cột so sánh CPM giữa các kênh
A5: 4 | B5: Tương tác | C5: Clicks / Link clicks | D5: Số lượt nhấp vào quảng cáo hoặc link về Landing Page | E5: Tổng từ báo cáo nền tảng | F5: Google Ads; Meta Insights; TikTok Analytics | G5: TV2; TV4 | H5: Nhap_SEM; Nhap_Social; Nhap_KOC | I5: Bước 7 | J5: Bảng theo kênh
A6: 5 | B6: Tương tác | C6: CTR | D6: Tỷ lệ nhấp trên lượt hiển thị | E6: Clicks ÷ Impressions | F6: Tính từ Clicks và Impressions | G6: TV1 tổng hợp | H6: Tong_hop_kenh | I6: Bước 7 | J6: Bảng theo kênh
A7: 6 | B7: Tương tác | C7: CPC | D7: Chi phí trung bình cho một lượt nhấp | E7: Chi phí ÷ Clicks | F7: Tính từ Chi phí và Clicks | G7: TV1 tổng hợp | H7: Tong_hop_kenh | I7: Bước 7, 10 | J7: Bảng; đối chiếu với dải giá thầu ở Transactional_Keywords
A8: 7 | B8: Traffic | C8: Organic Traffic (Sessions) | D8: Lượt truy cập Website/Landing Page từ kết quả tìm kiếm tự nhiên | E8: Tổng Sessions có Nguồn truy cập = Organic Search | F8: Google Analytics; Google Search Console | G8: TV3 | H8: Nhap_Traffic | I8: Bước 8 | J8: Đường theo ngày; cột so sánh với Paid
A9: 8 | B9: Traffic | C9: Paid Traffic (Sessions) | D9: Lượt truy cập từ quảng cáo trả phí (Google Ads, Meta/TikTok Ads) | E9: Tổng Sessions có Nhóm = Paid | F9: Google Analytics; báo cáo Ads | G9: TV3 | H9: Nhap_Traffic | I9: Bước 8 | J9: Đường theo ngày; cột so sánh với Organic
A10: 9 | B10: Traffic | C10: Social Traffic (Organic/Paid) | D10: Lượt truy cập từ Fanpage, TikTok, KOC, tách tự nhiên và trả phí | E10: Tổng Sessions theo Nguồn truy cập Social Organic, Social Paid, KOC | F10: Google Analytics; UTM; link ở bio | G10: TV3 và TV4 | H10: Nhap_Traffic | I10: Bước 8 | J10: Cột chồng theo nguồn
A11: 10 | B11: Ý định tìm kiếm | C11: Tỷ lệ nhóm Search Intent | D11: Tỷ trọng Commercial, Informational, Navigational, Transactional trong bộ 500 từ khóa | E11: Số từ khóa (hoặc lượt tìm) của nhóm ÷ tổng | F11: Sheet Intent_Summary của Giai đoạn 4 | G11: TV1 | H11: Nhap_Intent | I11: Bước 9 | J11: Biểu đồ tròn hoặc cột
A12: 11 | B12: Hiệu quả | C12: Đơn hàng | D12: Số đơn ghi nhận theo kênh tạo ra đơn | E12: Tổng từ bản ghi theo kênh | F12: Tin nhắn chốt đơn; hệ thống đơn hàng; mã KOC | G12: TV2; TV4 | H12: Nhap_SEM; Nhap_Social; Nhap_KOC | I12: Bước 9, 10 | J12: Bảng theo kênh
A13: 12 | B13: Hiệu quả | C13: Doanh thu | D13: Doanh thu thực tế (hoặc ước tính, có ghi chú) theo kênh | E13: Tổng từ bản ghi theo kênh | F13: Hệ thống đơn hàng | G13: TV2; TV4 | H13: Nhap_SEM; Nhap_Social; Nhap_KOC | I13: Bước 9 | J13: Cột so sánh với doanh thu dự kiến GĐ3
... A17: 16 | B17: Hiệu quả | C17: Lãi gộp dự kiến mỗi SKU | D17: Giá bán trừ giá vốn dự kiến, dùng làm mốc tham chiếu cho CAC | E17: Giá bán − Giá vốn | F17: Bước 1 Giai đoạn 4 (giá bán, giá vốn dự kiến) | G17: TV1 | H17: GD3_Dau_vao | I17: Bước 9, 10 | J17: Bảng

Sheet GD4_Dau_ra
A1: STT | B1: Hạng mục đầu ra Giai đoạn 4 | C1: Nội dung và vị trí lưu | D1: Người bàn giao | E1: Tình trạng ghi nhận ở Bước 10 GĐ4 | F1: Dùng ở GĐ5 (bước) | G1: Xác nhận hiện tại
A2: 1 | B2: Hero Product brief và checklist | C2: File Giai đoạn 4 – Bước 1; 10 SKU, USP, chân dung khách hàng, cấu trúc Landing Page | D2: TV1 – Phương Kiều | E2: Đã có; cần chốt SKU chính (đề xuất BT750-BK) và tên thương hiệu | F2: Bước 1, 9
A3: 2 | B3: Website/Landing Page | C3: Website 5 trang; URL chưa có; ảnh Hình 1–5 | D3: TV3 – Anh Khoa | E3: Cần URL, xác nhận nền tảng (PaaS hay WordPress), đối chiếu brief 9 khối | F3: Bước 2, 8
A4: 3 | B4: Nhóm từ khóa Transactional | C4: Sheet Transactional_Keywords, 27 từ khóa; phân loại: 10 dùng được, 6 giữ lại, 11 chưa chạy | D4: TV1 → TV2 | E4: Đã có | F4: Bước 2
A5: 4 | B5: Mẫu RSA | C5: Sheet RSA_Ads (4 mẫu), RSA_Kiem_Tra_Ky_Tu (52/52 đạt giới hạn ký tự); đề xuất chạy trước RSA 1, RSA 3 và phần 1000ml của RSA 4 | D5: TV2 – Phương Thúy | E5: Bản nháp; cần bổ sung tiêu đề có SOVA, dung tích, màu; hoãn RSA 2 | F5: Bước 2
A6: 5 | B6: Bảng Keyword–USP–CTA và checklist đồng bộ | C6: Sheet Keyword_USP_CTA, LandingPage_Check | D6: TV2, TV3 | E6: 9/10 mục checklist chưa có kết luận | F6: Bước 2, 10
A7: 6 | B7: Prompt Gen-AI | C7: Sheet Prompt_GenAI | D7: TV2 – Phương Thúy | E7: Cần chạy thật và chụp ảnh kết quả | F7: Bước 2
A8: 7 | B8: Fanpage | C8: Thông tin, nhận diện, 7 bài mẫu, lịch đăng 14 ngày (Bước 7 GĐ4) | D8: TV4 – Minh Thảo | E8: Cần tạo/hoàn thiện Page, điền Hotline/Zalo, chụp 5 ảnh | F8: Bước 3
A9: 8 | B9: TikTok | C9: Kênh Sovaa365, 3 kịch bản, hashtag, brief KOC (Bước 8 GĐ4) | D9: TV4 – Minh Thảo | E9: Cần chụp 3 ảnh; quay thử kịch bản 1 | F9: Bước 3, 4
A10: 9 | B10: Dữ liệu giá, ngân sách, chính sách | C10: Bảng 10 SKU; ngân sách GĐ3; bảo hành, đổi trả, giao hàng dự kiến | D10: TV1 – Phương Kiều | E10: Chính sách chưa có thời hạn cụ thể; giá Combo cần đối chiếu | F10: Bước 1, 9
A11: 10 | B11: Bộ minh chứng Chương III | C11: Ảnh và tệp theo bảng 9.3 (Bước 9 GĐ4) | D11: TV1 tổng hợp | E11: Chưa đủ; chờ các ảnh còn thiếu | F11: Bước 1

Sheet Ke_hoach
A1: Bước GĐ5 | B1: Hoạt động | C1: Phụ trách | D1: Phối hợp | E1: Điều kiện cần xong trước | F1: Dữ liệu và minh chứng thu được | G1: Ghi vào sheet | H1: Thời hạn | I1: Trạng thái
A2: Bước 2 | B2: Kích hoạt hoặc chuẩn bị chiến dịch SEM trên Google Ads bằng mẫu RSA Giai đoạn 4 | C2: TV2 – Phương Thúy | D2: TV1 – Phương Kiều | E2: URL Landing Page; checklist đồng bộ Keyword–RSA–Landing Page; ảnh chạy prompt thật | F2: Ảnh chiến dịch hoặc Preview Ads; chi phí, Impressions, Clicks nếu có chạy thật | G2: Nhap_SEM
A3: Bước 3 | B3: Đăng nội dung Fanpage và TikTok theo lịch 14 ngày; theo dõi Reach, Impressions | C3: TV4 – Minh Thảo | D3: TV3 – Anh Khoa | E3: Fanpage và TikTok đã tạo; điền Hotline/Zalo; thông số sản phẩm đã xác minh | F3: Reach, Impressions, lượt xem, tương tác, link clicks; ảnh minh chứng | G3: Nhap_Social
A4: Bước 4 | B4: Hợp tác 3–5 KOC; xác định vai trò tăng Reach | C4: TV4 – Minh Thảo | D4: TV2 – Phương Thúy | E4: Chọn số KOC (đề yêu cầu 3–5, GĐ3 giả định 8); brief KOC; chốt mã ưu đãi/link theo dõi | F4: Danh sách KOC, ngày đăng, views, Reach, đơn từ mã; ảnh hoặc kế hoạch | G4: Nhap_KOC
A5: Bước 5 | B5: Thu thập dữ liệu đa kênh: TV2 (SEM), TV3 (Organic/Paid Traffic), TV4 (Reach, Impressions, Social Traffic) | C5: TV2, TV3, TV4 | D5: TV1 chuẩn hóa | E5: Công cụ đo (Google Analytics, Meta Pixel) và UTM theo kênh đã cài | F5: Dữ liệu đa kênh đã chuẩn hóa | G5: Nhap_SEM; Nhap_Social; Nhap_KOC; Nhap_Traffic
A6: Bước 6 | B6: Kết nối Google Sheets với Looker Studio, kiểm tra trường dữ liệu | C6: TV1 – Phương Kiều | D6: TV2 – Phương Thúy | E6: File này đã đưa lên Google Sheets | F6: Dashboard nhận đúng dữ liệu | G6: Tong_hop_kenh và các sheet Nhap_*
A7: Bước 7 | B7: Trực quan hóa Reach, Impressions và CPM | C7: TV1 – Phương Kiều | D7: TV2, TV4 | E7: Dữ liệu SEM và Social đã nhập | F7: Dashboard Reach/Impressions và CPM | G7: Tong_hop_kenh
A8: Bước 8 | B8: Đo Organic Traffic và Paid Traffic | C8: TV3 – Anh Khoa | D8: TV1 tổng hợp | E8: Google Analytics/Search Console có dữ liệu | F8: Bảng Traffic và biểu đồ | G8: Nhap_Traffic
A9: Bước 9 | B9: Trực quan hóa Intent, doanh thu dự kiến, CAC và ROAS; đối chiếu GĐ3 | C9: TV1 – Phương Kiều | D9: Cả nhóm | E9: Điền CAC, ROAS, doanh thu dự kiến của GĐ3 vào GD3_Dau_vao | F9: Dashboard tổng hợp | G9: Nhap_Intent; Tong_hop_kenh; GD3_Dau_vao
A10: Bước 10 | B10: Quản trị rủi ro và Pivot (tình huống CAC tăng 20%) | C10: TV1 – Phương Kiều | D10: Cả nhóm | E10: Dashboard hoạt động | F10: Bảng Risk → KPI → Nguyên nhân → Pivot → Kết quả dự kiến | G10: Tong_hop_kenh (cột Cảnh báo)

Sheet GD3_Dau_vao
A1: Hạng mục | B1: Giá trị | C1: Đơn vị | D1: Nguồn / ghi chú
A2: Ngân sách Meta Ads mỗi tháng | B2: 7500000 | C2: VND | D2: Giai đoạn 3, trích trong Bước 7 file Giai đoạn 4
A3: Ngân sách boost TikTok mỗi tháng | B3: 6000000 | C3: VND | D3: Giai đoạn 3, trích trong Bước 8 file Giai đoạn 4
A4: Số KOC theo Giai đoạn 3 | B4: 5 | C4: KOC | D4: Giai đoạn 5 chốt 5 KOC theo yêu cầu đề; thay giả định 8 KOC ở GĐ3.
A5: Phí đăng mỗi KOC | B5: 500000 | C5: VND | D5: Giai đoạn 3 (mục 8.6)
A6: Giá vốn bình 500ml gửi seeding | B6: 95000 | C6: VND | D6: Giá vốn dự kiến, Bước 1 Giai đoạn 4
A7: Chi phí KOC theo Giai đoạn 3 | B7: =B4*(B5+B6+30000) -> 3125000 | C7: VND | D7: Công thức gồm phí đăng 500.000 + giá vốn seeding 95.000 + vận chuyển 30.000/KOC; mô phỏng.
A8: Ngân sách Google Ads mỗi tháng | B8: 15000000 | C8: VND | D8: Theo tài liệu GĐ5: ngân sách Google Ads dự kiến từ GĐ3, 15.000.000 VND/tháng; cần đối chiếu file GĐ3 gốc.
A9: Doanh thu dự kiến Giai đoạn 3 | C9: VND | D9: Lấy từ Giai đoạn 3
A10: CAC dự kiến Giai đoạn 3 | C10: VND/đơn | D10: Lấy từ Giai đoạn 3; dùng làm mốc cảnh báo
A11: ROAS dự kiến Giai đoạn 3 | C11: lần | D11: Lấy từ Giai đoạn 3
A12: Ngưỡng cảnh báo CAC tăng | B12: 0.2 | C12: % | D12: Đề bài (tình huống CAC tăng 20% do đối thủ cạnh tranh giá thầu)
A13: Số KOC thực hiện ở Giai đoạn 5 | C13: KOC | D13: Đề yêu cầu 3–5 KOC; nhóm chọn số cụ thể
A15: Giá bán và giá vốn dự kiến (Bước 1 Giai đoạn 4)
A16: SKU | B16: Giá bán (VND) | C16: Giá vốn dự kiến (VND) | D16: Lãi gộp (VND) | E16: Biên lãi gộp
A17: Bình 500ml | B17: 199000 | C17: 95000 | D17: =B17-C17 -> 104000 | E17: =D17/B17 -> 0.52261307
A18: Bình 750ml | B18: 229000 | C18: 110000 | D18: =B18-C18 -> 119000 | E18: =D18/B18 -> 0.51965066
A19: Bình 1000ml | B19: 269000 | C19: 130000 | D19: =B19-C19 -> 139000 | E19: =D19/B19 -> 0.51672862

Sheet Nhap_SEM
A1: Ngày | B1: Chiến dịch | C1: Nhóm quảng cáo | D1: Từ khóa chính | E1: Chi phí (VND) | F1: Impressions | G1: Clicks | H1: Đơn hàng | I1: Doanh thu (VND) | J1: Ghi chú nguồn/trạng thái
B2: SOVA – Search – Bình giữ nhiệt | C2: Preview/kế hoạch – RSA A và RSA B | D2: bình giữ nhiệt giá rẻ; giá bình giữ nhiệt; mua bình giữ nhiệt | J2: Preview/kế hoạch; chưa nhập số liệu hiệu suất thực tế. Cập nhật từ báo cáo nền tảng khi có.

Sheet Nhap_KOC
A1: KOC_ID | B1: Tên kênh | C1: Nền tảng | D1: Link bài/video | E1: Ngày đăng | F1: Phí đăng (VND) | G1: Chi phí seeding (VND) | H1: Views | I1: Reach | J1: Impressions | K1: Link clicks | L1: Đơn hàng (mã KOC) | M1: Doanh thu (VND) | N1: Trạng thái
A2: KOC-01 | B2: @ltthuhinn | C2: TikTok | F2: 500000 | G2: 125000 | N2: Đề xuất – chưa liên hệ
A3: KOC-02 | B3: @minimeow154 | C3: TikTok | F3: 500000 | G3: 125000 | N3: Đề xuất – chưa liên hệ
A4: KOC-03 | B4: @quyendigym | C4: TikTok | F4: 500000 | G4: 125000 | N4: Đề xuất – chưa liên hệ
A5: KOC-04 | B5: @hoang.real.review | C5: TikTok | F5: 500000 | G5: 125000 | N5: Đề xuất – chưa liên hệ
A6: KOC-05 | B6: @tinkerboong | C6: TikTok | F6: 500000 | G6: 125000 | N6: Đề xuất – chưa liên hệ

Sheet Nhap_Traffic
A1: Ngày | B1: Nguồn truy cập | C1: Nhóm | D1: Sessions | E1: Users | F1: Ghi chú nguồn
A2: 46296 | B2: Organic Search | C2: Organic | D2: 42 | E2: 34 | F2: GA4 + Search Console; Sessions từ GA4; Clicks/Impressions từ Search Console. DỮ LIỆU MÔ PHỎNG, không phải số liệu GA4/Ads thực tế.
A3: 46296 | B3: Google Ads | C3: Paid | D3: 31 | E3: 25 | F3: GA4 + Google Ads; Sessions khác Clicks; không cộng hai chỉ số với nhau. DỮ LIỆU MÔ PHỎNG, không phải số liệu GA4/Ads thực tế.
A4: 46296 | B4: Facebook/TikTok (mô phỏng) | C4: Social Organic | D4: 12 | E4: 10 | F4: GA4 + Meta Insights ; Social Traffic không trả phí; Reach/Impressions từ mạng xã hội. DỮ LIỆU MÔ PHỎNG, không phải số liệu GA4/Ads thực tế.
A5: 46297 | B5: Organic Search | C5: Organic | D5: 48 | E5: 39 | F5: GA4 + Search Console ; Sessions từ GA4; Clicks/Impressions từ Search Console. DỮ LIỆU MÔ PHỎNG, không phải số liệu GA4/Ads thực tế.
A6: 46297 | B6: Google Ads | C6: Paid | D6: 35 | E6: 29 | F6: GA4 + Google Ads ; Sessions khác Clicks; không cộng hai chỉ số với nhau. DỮ LIỆU MÔ PHỎNG, không phải số liệu GA4/Ads thực tế.
A7: 46297 | B7: Facebook/TikTok (mô phỏng) | C7: Social Organic | D7: 14 | E7: 11 | F7: GA4 + Meta Insights ; Social Traffic không trả phí; Reach/Impressions từ mạng xã hội. DỮ LIỆU MÔ PHỎNG, không phải số liệu GA4/Ads thực tế.
A8: 46298 | B8: Organic Search | C8: Organic | D8: 45 | E8: 37 | F8: GA4 + Search Console ; Sessions từ GA4; Clicks/Impressions từ Search Console. DỮ LIỆU MÔ PHỎNG, không phải số liệu GA4/Ads thực tế.
A9: 46298 | B9: Google Ads | C9: Paid | D9: 33 | E9: 27 | F9: GA4 + Google Ads ; Sessions khác Clicks; không cộng hai chỉ số với nhau. DỮ LIỆU MÔ PHỎNG, không phải số liệu GA4/Ads thực tế.
A10: 46298 | B10: Facebook/TikTok (mô phỏng) | C10: Social Organic | D10: 13 | E10: 11 | F10: GA4 + Meta Insights ; Social Traffic không trả phí; Reach/Impressions từ mạng xã hội. DỮ LIỆU MÔ PHỎNG, không phải số liệu GA4/Ads thực tế.
A11: 46299 | B11: Organic Search | C11: Organic | D11: 53 | E11: 43 | F11: GA4 + Search Console; Sessions từ GA4; Clicks/Impressions từ Search Console. DỮ LIỆU MÔ PHỎNG, không phải số liệu GA4/Ads thực tế.
A12: 46299 | B12: Google Ads | C12: Paid | D12: 38 | E12: 31 | F12: GA4 + Google Ads; Sessions khác Clicks; không cộng hai chỉ số với nhau. DỮ LIỆU MÔ PHỎNG, không phải số liệu GA4/Ads thực tế.
A13: 46299 | B13: Facebook/TikTok (mô phỏng) | C13: Social Organic | D13: 16 | E13: 13 | F13: GA4 + Meta Insights ; Social Traffic không trả phí; Reach/Impressions từ mạng xã hội. DỮ LIỆU MÔ PHỎNG, không phải số liệu GA4/Ads thực tế.
... A43: 46309 | B43: Facebook/TikTok (mô phỏng) | C43: Social Organic | D43: 27 | E43: 22 | F43: GA4 + Meta Insights; Social Traffic không trả phí; Reach/Impressions từ mạng xã hội. DỮ LIỆU MÔ PHỎNG, không phải số liệu GA4/Ads thực tế.

Sheet Nhap_Intent
A1: Search_Intent | B1: So_keyword | C1: Luot_tim_thang | D1: Ty_le_theo_keyword | E1: Ty_le_theo_luot_tim
A2: Commercial | B2: 318 | C2: 124350 | D2: =B2/SUM($B$2:$B$5) -> 0.636 | E2: =C2/SUM($C$2:$C$5) -> 0.60393395
A3: Informational | B3: 21 | C3: 2850 | D3: =B3/SUM($B$2:$B$5) -> 0.042 | E3: =C3/SUM($C$2:$C$5) -> 0.013841671
A4: Navigational | B4: 134 | C4: 71950 | D4: =B4/SUM($B$2:$B$5) -> 0.268 | E4: =C4/SUM($C$2:$C$5) -> 0.34944148
A5: Transactional | B5: 27 | C5: 6750 | D5: =B5/SUM($B$2:$B$5) -> 0.054 | E5: =C5/SUM($C$2:$C$5) -> 0.032782904
A8: Nguồn: sheet Intent_Summary (file Buoc_456.xlsx, Bước 4 Giai đoạn 4), bộ 500 từ khóa. Tỷ lệ gốc Ty_le_% trong file nguồn tính theo số từ khóa; cột Ty_le_theo_luot_tim thêm để so sánh theo nhu cầu tìm kiếm.

Sheet Tong_hop_kenh
A1: Kênh | B1: Chi phí (VND) | C1: Impressions | D1: Reach | E1: Clicks | F1: Đơn hàng | G1: Doanh thu (VND) | H1: CPM (VND) | I1: CTR | J1: CPC (VND) | K1: CAC (VND/đơn) | L1: ROAS (lần) | M1: CAC dự kiến GĐ3 | N1: Cảnh báo CAC
A2: Google Ads (SEM) | B2: =SUM(Nhap_SEM!E2:E1000) -> 0 | C2: =SUM(Nhap_SEM!F2:F1000) -> 0 | E2: =SUM(Nhap_SEM!G2:G1000) -> 0 | F2: =SUM(Nhap_SEM!H2:H1000) -> 0 | G2: =SUM(Nhap_SEM!I2:I1000) -> 0 | H2: =IF(C2=0,"",B2/C2*1000) | I2: =IF(C2=0,"",E2/C2) | J2: =IF(E2=0,"",B2/E2) | K2: =IF(F2=0,"",B2/F2) | L2: =IF(B2=0,"",G2/B2) | M2: =IF(GD3_Dau_vao!B10="","",GD3_Dau_vao!B10) | N2: =IF(OR(K2="",M2=""),"",IF(K2>=M2*(1+GD3_Dau_vao!B12),"Vượt ngưỡng","Trong ngưỡng"))
A3: Fanpage | B3: =SUMIFS(#REF!,#REF!,$A3) -> #REF! | C3: =SUMIFS(#REF!,#REF!,$A3) -> #REF! | D3: =SUMIFS(#REF!,#REF!,$A3) -> #REF! | E3: =SUMIFS(#REF!,#REF!,$A3) -> #REF! | F3: =SUMIFS(#REF!,#REF!,$A3) -> #REF! | G3: =SUMIFS(#REF!,#REF!,$A3) -> #REF! | H3: =IF(C3=0,"",B3/C3*1000) -> #REF! | I3: =IF(C3=0,"",E3/C3) -> #REF! | J3: =IF(E3=0,"",B3/E3) -> #REF! | K3: =IF(F3=0,"",B3/F3) -> #REF! | L3: =IF(B3=0,"",G3/B3) -> #REF! | M3: =IF(GD3_Dau_vao!B10="","",GD3_Dau_vao!B10) | N3: =IF(OR(K3="",M3=""),"",IF(K3>=M3*(1+GD3_Dau_vao!B12),"Vượt ngưỡng","Trong ngưỡng")) -> #REF!
A4: TikTok | B4: =SUMIFS(#REF!,#REF!,$A4) -> #REF! | C4: =SUMIFS(#REF!,#REF!,$A4) -> #REF! | D4: =SUMIFS(#REF!,#REF!,$A4) -> #REF! | E4: =SUMIFS(#REF!,#REF!,$A4) -> #REF! | F4: =SUMIFS(#REF!,#REF!,$A4) -> #REF! | G4: =SUMIFS(#REF!,#REF!,$A4) -> #REF! | H4: =IF(C4=0,"",B4/C4*1000) -> #REF! | I4: =IF(C4=0,"",E4/C4) -> #REF! | J4: =IF(E4=0,"",B4/E4) -> #REF! | K4: =IF(F4=0,"",B4/F4) -> #REF! | L4: =IF(B4=0,"",G4/B4) -> #REF! | M4: =IF(GD3_Dau_vao!B10="","",GD3_Dau_vao!B10) | N4: =IF(OR(K4="",M4=""),"",IF(K4>=M4*(1+GD3_Dau_vao!B12),"Vượt ngưỡng","Trong ngưỡng")) -> #REF!
A5: KOC | B5: =SUM(Nhap_KOC!F2:F1000)+SUM(Nhap_KOC!G2:G1000) -> 3125000 | C5: =SUM(Nhap_KOC!J2:J1000) -> 0 | D5: =SUM(Nhap_KOC!I2:I1000) -> 0 | E5: =SUM(Nhap_KOC!K2:K1000) -> 0 | F5: =SUM(Nhap_KOC!L2:L1000) -> 0 | G5: =SUM(Nhap_KOC!M2:M1000) -> 0 | H5: =IF(C5=0,"",B5/C5*1000) | I5: =IF(C5=0,"",E5/C5) | J5: =IF(E5=0,"",B5/E5) | K5: =IF(F5=0,"",B5/F5) | L5: =IF(B5=0,"",G5/B5) -> 0 | M5: =IF(GD3_Dau_vao!B10="","",GD3_Dau_vao!B10) | N5: =IF(OR(K5="",M5=""),"",IF(K5>=M5*(1+GD3_Dau_vao!B12),"Vượt ngưỡng","Trong ngưỡng"))
A6: Tổng cộng | B6: =SUM(B2:B5) -> #REF! | C6: =SUM(C2:C5) -> #REF! | D6: =SUM(D2:D5) -> #REF! | E6: =SUM(E2:E5) -> #REF! | F6: =SUM(F2:F5) -> #REF! | G6: =SUM(G2:G5) -> #REF! | H6: =IF(C6=0,"",B6/C6*1000) -> #REF! | I6: =IF(C6=0,"",E6/C6) -> #REF! | J6: =IF(E6=0,"",B6/E6) -> #REF! | K6: =IF(F6=0,"",B6/F6) -> #REF! | L6: =IF(B6=0,"",G6/B6) -> #REF! | M6: =IF(GD3_Dau_vao!B10="","",GD3_Dau_vao!B10) | N6: =IF(OR(K6="",M6=""),"",IF(K6>=M6*(1+GD3_Dau_vao!B12),"Vượt ngưỡng","Trong ngưỡng")) -> #REF!

Sheet Sheet1
A1: BƯỚC 5 – DỮ LIỆU THÔ ĐA KÊNH (MÔ PHỎNG)
A4: Ngày | B4: Kênh | C4: Phụ trách | D4: Nguồn công cụ | E4: Sessions | F4: Clicks | G4: Impressions | H4: Reach | I4: Chi phí (VND) | J4: Ghi chú
A5: 46296 | B5: Organic | C5: TV3 – Anh Khoa | D5: GA4 + Search Console | E5: 42 | F5: 28 | G5: 610 | I5: 0 | J5: Sessions từ GA4; Clicks/Impressions từ Search Console.
A6: 46296 | B6: Paid | C6: TV3 – Anh Khoa / TV2 – Phương Thúy | D6: GA4 + Google Ads | E6: 31 | F6: 42 | G6: 1500 | I6: 126000 | J6: Sessions khác Clicks; không cộng hai chỉ số với nhau.
A7: 46296 | B7: Social Organic | C7: TV4 – Minh Thảo | D7: GA4 + Meta Insights | E7: 12 | F7: 17 | G7: 980 | H7: 720 | I7: 0 | J7: Social Traffic không trả phí; Reach/Impressions từ mạng xã hội.
A8: 46297 | B8: Organic | C8: TV3 – Anh Khoa | D8: GA4 + Search Console | E8: 48 | F8: 31 | G8: 650 | I8: 0 | J8: Sessions từ GA4; Clicks/Impressions từ Search Console.
A9: 46297 | B9: Paid | C9: TV3 – Anh Khoa / TV2 – Phương Thúy | D9: GA4 + Google Ads | E9: 35 | F9: 46 | G9: 1620 | I9: 138000 | J9: Sessions khác Clicks; không cộng hai chỉ số với nhau.
A10: 46297 | B10: Social Organic | C10: TV4 – Minh Thảo | D10: GA4 + Meta Insights | E10: 14 | F10: 19 | G10: 1050 | H10: 770 | I10: 0 | J10: Social Traffic không trả phí; Reach/Impressions từ mạng xã hội.
A11: 46298 | B11: Organic | C11: TV3 – Anh Khoa | D11: GA4 + Search Console | E11: 45 | F11: 29 | G11: 630 | I11: 0 | J11: Sessions từ GA4; Clicks/Impressions từ Search Console.
A12: 46298 | B12: Paid | C12: TV3 – Anh Khoa / TV2 – Phương Thúy | D12: GA4 + Google Ads | E12: 33 | F12: 44 | G12: 1580 | I12: 132000 | J12: Sessions khác Clicks; không cộng hai chỉ số với nhau.
A13: 46298 | B13: Social Organic | C13: TV4 – Minh Thảo | D13: GA4 + Meta Insights | E13: 13 | F13: 18 | G13: 1010 | H13: 745 | I13: 0 | J13: Social Traffic không trả phí; Reach/Impressions từ mạng xã hội.
A14: 46299 | B14: Organic | C14: TV3 – Anh Khoa | D14: GA4 + Search Console | E14: 53 | F14: 34 | G14: 700 | I14: 0 | J14: Sessions từ GA4; Clicks/Impressions từ Search Console.
A15: 46299 | B15: Paid | C15: TV3 – Anh Khoa / TV2 – Phương Thúy | D15: GA4 + Google Ads | E15: 38 | F15: 50 | G15: 1750 | I15: 150000 | J15: Sessions khác Clicks; không cộng hai chỉ số với nhau.
A16: 46299 | B16: Social Organic | C16: TV4 – Minh Thảo | D16: GA4 + Meta Insights | E16: 16 | F16: 21 | G16: 1140 | H16: 830 | I16: 0 | J16: Social Traffic không trả phí; Reach/Impressions từ mạng xã hội.
A17: 46300 | B17: Organic | C17: TV3 – Anh Khoa | D17: GA4 + Search Console | E17: 57 | F17: 37 | G17: 740 | I17: 0 | J17: Sessions từ GA4; Clicks/Impressions từ Search Console.
A18: 46300 | B18: Paid | C18: TV3 – Anh Khoa / TV2 – Phương Thúy | D18: GA4 + Google Ads | E18: 42 | F18: 55 | G18: 1880 | I18: 165000 | J18: Sessions khác Clicks; không cộng hai chỉ số với nhau.
A19: 46300 | B19: Social Organic | C19: TV4 – Minh Thảo | D19: GA4 + Meta Insights | E19: 18 | F19: 24 | G19: 1240 | H19: 890 | I19: 0 | J19: Social Traffic không trả phí; Reach/Impressions từ mạng xã hội.
A20: 46301 | B20: Organic | C20: TV3 – Anh Khoa | D20: GA4 + Search Console | E20: 51 | F20: 33 | G20: 715 | I20: 0 | J20: Sessions từ GA4; Clicks/Impressions từ Search Console.
A21: 46301 | B21: Paid | C21: TV3 – Anh Khoa / TV2 – Phương Thúy | D21: GA4 + Google Ads | E21: 37 | F21: 49 | G21: 1810 | I21: 147000 | J21: Sessions khác Clicks; không cộng hai chỉ số với nhau.
A22: 46301 | B22: Social Organic | C22: TV4 – Minh Thảo | D22: GA4 + Meta Insights | E22: 15 | F22: 20 | G22: 1180 | H22: 850 | I22: 0 | J22: Social Traffic không trả phí; Reach/Impressions từ mạng xã hội.
A23: 46302 | B23: Organic | C23: TV3 – Anh Khoa | D23: GA4 + Search Console | E23: 60 | F23: 39 | G23: 780 | I23: 0 | J23: Sessions từ GA4; Clicks/Impressions từ Search Console.
A24: 46302 | B24: Paid | C24: TV3 – Anh Khoa / TV2 – Phương Thúy | D24: GA4 + Google Ads | E24: 44 | F24: 58 | G24: 1990 | I24: 174000 | J24: Sessions khác Clicks; không cộng hai chỉ số với nhau.
A25: 46302 | B25: Social Organic | C25: TV4 – Minh Thảo | D25: GA4 + Meta Insights | E25: 19 | F25: 25 | G25: 1300 | H25: 930 | I25: 0 | J25: Social Traffic không trả phí; Reach/Impressions từ mạng xã hội.
A26: 46303 | B26: Organic | C26: TV3 – Anh Khoa | D26: GA4 + Search Console | E26: 62 | F26: 41 | G26: 810 | I26: 0 | J26: Sessions từ GA4; Clicks/Impressions từ Search Console.
A27: 46303 | B27: Paid | C27: TV3 – Anh Khoa / TV2 – Phương Thúy | D27: GA4 + Google Ads | E27: 46 | F27: 60 | G27: 2050 | I27: 180000 | J27: Sessions khác Clicks; không cộng hai chỉ số với nhau.
A28: 46303 | B28: Social Organic | C28: TV4 – Minh Thảo | D28: GA4 + Meta Insights | E28: 20 | F28: 27 | G28: 1380 | H28: 990 | I28: 0 | J28: Social Traffic không trả phí; Reach/Impressions từ mạng xã hội.
A29: 46304 | B29: Organic | C29: TV3 – Anh Khoa | D29: GA4 + Search Console | E29: 58 | F29: 38 | G29: 790 | I29: 0 | J29: Sessions từ GA4; Clicks/Impressions từ Search Console.
A30: 46304 | B30: Paid | C30: TV3 – Anh Khoa / TV2 – Phương Thúy | D30: GA4 + Google Ads | E30: 43 | F30: 57 | G30: 2010 | I30: 171000 | J30: Sessions khác Clicks; không cộng hai chỉ số với nhau.
A31: 46304 | B31: Social Organic | C31: TV4 – Minh Thảo | D31: GA4 + Meta Insights | E31: 18 | F31: 24 | G31: 1330 | H31: 950 | I31: 0 | J31: Social Traffic không trả phí; Reach/Impressions từ mạng xã hội.
A32: 46305 | B32: Organic | C32: TV3 – Anh Khoa | D32: GA4 + Search Console | E32: 65 | F32: 43 | G32: 860 | I32: 0 | J32: Sessions từ GA4; Clicks/Impressions từ Search Console.
A33: 46305 | B33: Paid | C33: TV3 – Anh Khoa / TV2 – Phương Thúy | D33: GA4 + Google Ads | E33: 48 | F33: 63 | G33: 2180 | I33: 189000 | J33: Sessions khác Clicks; không cộng hai chỉ số với nhau.
A34: 46305 | B34: Social Organic | C34: TV4 – Minh Thảo | D34: GA4 + Meta Insights | E34: 22 | F34: 29 | G34: 1480 | H34: 1050 | I34: 0 | J34: Social Traffic không trả phí; Reach/Impressions từ mạng xã hội.
A35: 46306 | B35: Organic | C35: TV3 – Anh Khoa | D35: GA4 + Search Console | E35: 68 | F35: 45 | G35: 900 | I35: 0 | J35: Sessions từ GA4; Clicks/Impressions từ Search Console.
A36: 46306 | B36: Paid | C36: TV3 – Anh Khoa / TV2 – Phương Thúy | D36: GA4 + Google Ads | E36: 50 | F36: 66 | G36: 2270 | I36: 198000 | J36: Sessions khác Clicks; không cộng hai chỉ số với nhau.
A37: 46306 | B37: Social Organic | C37: TV4 – Minh Thảo | D37: GA4 + Meta Insights | E37: 23 | F37: 31 | G37: 1550 | H37: 1110 | I37: 0 | J37: Social Traffic không trả phí; Reach/Impressions từ mạng xã hội.
A38: 46307 | B38: Organic | C38: TV3 – Anh Khoa | D38: GA4 + Search Console | E38: 64 | F38: 42 | G38: 875 | I38: 0 | J38: Sessions từ GA4; Clicks/Impressions từ Search Console.
A39: 46307 | B39: Paid | C39: TV3 – Anh Khoa / TV2 – Phương Thúy | D39: GA4 + Google Ads | E39: 47 | F39: 62 | G39: 2200 | I39: 186000 | J39: Sessions khác Clicks; không cộng hai chỉ số với nhau.
A40: 46307 | B40: Social Organic | C40: TV4 – Minh Thảo | D40: GA4 + Meta Insights | E40: 21 | F40: 28 | G40: 1500 | H40: 1080 | I40: 0 | J40: Social Traffic không trả phí; Reach/Impressions từ mạng xã hội.
A41: 46308 | B41: Organic | C41: TV3 – Anh Khoa | D41: GA4 + Search Console | E41: 71 | F41: 47 | G41: 940 | I41: 0 | J41: Sessions từ GA4; Clicks/Impressions từ Search Console.
A42: 46308 | B42: Paid | C42: TV3 – Anh Khoa / TV2 – Phương Thúy | D42: GA4 + Google Ads | E42: 53 | F42: 69 | G42: 2390 | I42: 207000 | J42: Sessions khác Clicks; không cộng hai chỉ số với nhau.
...

Sheet Traffic_Mo_phong
A1: Ngày | B1: Kênh | C1: Phụ trách | D1: Nguồn công cụ giả định | E1: Sessions | F1: Clicks | G1: Impressions | H1: Reach | I1: Chi phí (VND) | J1: Loại dữ liệu | K1: Ghi chú
A2: 46296 | B2: Organic | C2: TV3 – Anh Khoa | D2: GA4 + Search Console | E2: 42 | F2: 28 | G2: 610 | I2: 0 | J2: Ước tính/mô phỏng | K2: Sessions từ GA4; Clicks/Impressions từ Search Console.
A3: 46296 | B3: Paid | C3: TV3 – Anh Khoa / TV2 – Phương Thúy | D3: GA4 + Google Ads | E3: 31 | F3: 42 | G3: 1500 | I3: 126000 | J3: Ước tính/mô phỏng | K3: Sessions khác Clicks; không cộng hai chỉ số với nhau.
A4: 46296 | B4: Social Organic | C4: TV4 – Minh Thảo | D4: GA4 + Meta Insights | E4: 12 | F4: 17 | G4: 980 | H4: 720 | I4: 0 | J4: Ước tính/mô phỏng | K4: Social Traffic không trả phí; Reach/Impressions từ mạng xã hội.
A5: 46297 | B5: Organic | C5: TV3 – Anh Khoa | D5: GA4 + Search Console | E5: 48 | F5: 31 | G5: 650 | I5: 0 | J5: Ước tính/mô phỏng | K5: Sessions từ GA4; Clicks/Impressions từ Search Console.
A6: 46297 | B6: Paid | C6: TV3 – Anh Khoa / TV2 – Phương Thúy | D6: GA4 + Google Ads | E6: 35 | F6: 46 | G6: 1620 | I6: 138000 | J6: Ước tính/mô phỏng | K6: Sessions khác Clicks; không cộng hai chỉ số với nhau.
A7: 46297 | B7: Social Organic | C7: TV4 – Minh Thảo | D7: GA4 + Meta Insights | E7: 14 | F7: 19 | G7: 1050 | H7: 770 | I7: 0 | J7: Ước tính/mô phỏng | K7: Social Traffic không trả phí; Reach/Impressions từ mạng xã hội.
A8: 46298 | B8: Organic | C8: TV3 – Anh Khoa | D8: GA4 + Search Console | E8: 45 | F8: 29 | G8: 630 | I8: 0 | J8: Ước tính/mô phỏng | K8: Sessions từ GA4; Clicks/Impressions từ Search Console.
A9: 46298 | B9: Paid | C9: TV3 – Anh Khoa / TV2 – Phương Thúy | D9: GA4 + Google Ads | E9: 33 | F9: 44 | G9: 1580 | I9: 132000 | J9: Ước tính/mô phỏng | K9: Sessions khác Clicks; không cộng hai chỉ số với nhau.
A10: 46298 | B10: Social Organic | C10: TV4 – Minh Thảo | D10: GA4 + Meta Insights | E10: 13 | F10: 18 | G10: 1010 | H10: 745 | I10: 0 | J10: Ước tính/mô phỏng | K10: Social Traffic không trả phí; Reach/Impressions từ mạng xã hội.
A11: 46299 | B11: Organic | C11: TV3 – Anh Khoa | D11: GA4 + Search Console | E11: 53 | F11: 34 | G11: 700 | I11: 0 | J11: Ước tính/mô phỏng | K11: Sessions từ GA4; Clicks/Impressions từ Search Console.
A12: 46299 | B12: Paid | C12: TV3 – Anh Khoa / TV2 – Phương Thúy | D12: GA4 + Google Ads | E12: 38 | F12: 50 | G12: 1750 | I12: 150000 | J12: Ước tính/mô phỏng | K12: Sessions khác Clicks; không cộng hai chỉ số với nhau.
A13: 46299 | B13: Social Organic | C13: TV4 – Minh Thảo | D13: GA4 + Meta Insights | E13: 16 | F13: 21 | G13: 1140 | H13: 830 | I13: 0 | J13: Ước tính/mô phỏng | K13: Social Traffic không trả phí; Reach/Impressions từ mạng xã hội.
A14: 46300 | B14: Organic | C14: TV3 – Anh Khoa | D14: GA4 + Search Console | E14: 57 | F14: 37 | G14: 740 | I14: 0 | J14: Ước tính/mô phỏng | K14: Sessions từ GA4; Clicks/Impressions từ Search Console.
A15: 46300 | B15: Paid | C15: TV3 – Anh Khoa / TV2 – Phương Thúy | D15: GA4 + Google Ads | E15: 42 | F15: 55 | G15: 1880 | I15: 165000 | J15: Ước tính/mô phỏng | K15: Sessions khác Clicks; không cộng hai chỉ số với nhau.
A16: 46300 | B16: Social Organic | C16: TV4 – Minh Thảo | D16: GA4 + Meta Insights | E16: 18 | F16: 24 | G16: 1240 | H16: 890 | I16: 0 | J16: Ước tính/mô phỏng | K16: Social Traffic không trả phí; Reach/Impressions từ mạng xã hội.
A17: 46301 | B17: Organic | C17: TV3 – Anh Khoa | D17: GA4 + Search Console | E17: 51 | F17: 33 | G17: 715 | I17: 0 | J17: Ước tính/mô phỏng | K17: Sessions từ GA4; Clicks/Impressions từ Search Console.
A18: 46301 | B18: Paid | C18: TV3 – Anh Khoa / TV2 – Phương Thúy | D18: GA4 + Google Ads | E18: 37 | F18: 49 | G18: 1810 | I18: 147000 | J18: Ước tính/mô phỏng | K18: Sessions khác Clicks; không cộng hai chỉ số với nhau.
A19: 46301 | B19: Social Organic | C19: TV4 – Minh Thảo | D19: GA4 + Meta Insights | E19: 15 | F19: 20 | G19: 1180 | H19: 850 | I19: 0 | J19: Ước tính/mô phỏng | K19: Social Traffic không trả phí; Reach/Impressions từ mạng xã hội.
A20: 46302 | B20: Organic | C20: TV3 – Anh Khoa | D20: GA4 + Search Console | E20: 60 | F20: 39 | G20: 780 | I20: 0 | J20: Ước tính/mô phỏng | K20: Sessions từ GA4; Clicks/Impressions từ Search Console.
A21: 46302 | B21: Paid | C21: TV3 – Anh Khoa / TV2 – Phương Thúy | D21: GA4 + Google Ads | E21: 44 | F21: 58 | G21: 1990 | I21: 174000 | J21: Ước tính/mô phỏng | K21: Sessions khác Clicks; không cộng hai chỉ số với nhau.
A22: 46302 | B22: Social Organic | C22: TV4 – Minh Thảo | D22: GA4 + Meta Insights | E22: 19 | F22: 25 | G22: 1300 | H22: 930 | I22: 0 | J22: Ước tính/mô phỏng | K22: Social Traffic không trả phí; Reach/Impressions từ mạng xã hội.
A23: 46303 | B23: Organic | C23: TV3 – Anh Khoa | D23: GA4 + Search Console | E23: 62 | F23: 41 | G23: 810 | I23: 0 | J23: Ước tính/mô phỏng | K23: Sessions từ GA4; Clicks/Impressions từ Search Console.
A24: 46303 | B24: Paid | C24: TV3 – Anh Khoa / TV2 – Phương Thúy | D24: GA4 + Google Ads | E24: 46 | F24: 60 | G24: 2050 | I24: 180000 | J24: Ước tính/mô phỏng | K24: Sessions khác Clicks; không cộng hai chỉ số với nhau.
A25: 46303 | B25: Social Organic | C25: TV4 – Minh Thảo | D25: GA4 + Meta Insights | E25: 20 | F25: 27 | G25: 1380 | H25: 990 | I25: 0 | J25: Ước tính/mô phỏng | K25: Social Traffic không trả phí; Reach/Impressions từ mạng xã hội.
A26: 46304 | B26: Organic | C26: TV3 – Anh Khoa | D26: GA4 + Search Console | E26: 58 | F26: 38 | G26: 790 | I26: 0 | J26: Ước tính/mô phỏng | K26: Sessions từ GA4; Clicks/Impressions từ Search Console.
A27: 46304 | B27: Paid | C27: TV3 – Anh Khoa / TV2 – Phương Thúy | D27: GA4 + Google Ads | E27: 43 | F27: 57 | G27: 2010 | I27: 171000 | J27: Ước tính/mô phỏng | K27: Sessions khác Clicks; không cộng hai chỉ số với nhau.
A28: 46304 | B28: Social Organic | C28: TV4 – Minh Thảo | D28: GA4 + Meta Insights | E28: 18 | F28: 24 | G28: 1330 | H28: 950 | I28: 0 | J28: Ước tính/mô phỏng | K28: Social Traffic không trả phí; Reach/Impressions từ mạng xã hội.
A29: 46305 | B29: Organic | C29: TV3 – Anh Khoa | D29: GA4 + Search Console | E29: 65 | F29: 43 | G29: 860 | I29: 0 | J29: Ước tính/mô phỏng | K29: Sessions từ GA4; Clicks/Impressions từ Search Console.
A30: 46305 | B30: Paid | C30: TV3 – Anh Khoa / TV2 – Phương Thúy | D30: GA4 + Google Ads | E30: 48 | F30: 63 | G30: 2180 | I30: 189000 | J30: Ước tính/mô phỏng | K30: Sessions khác Clicks; không cộng hai chỉ số với nhau.
A31: 46305 | B31: Social Organic | C31: TV4 – Minh Thảo | D31: GA4 + Meta Insights | E31: 22 | F31: 29 | G31: 1480 | H31: 1050 | I31: 0 | J31: Ước tính/mô phỏng | K31: Social Traffic không trả phí; Reach/Impressions từ mạng xã hội.
A32: 46306 | B32: Organic | C32: TV3 – Anh Khoa | D32: GA4 + Search Console | E32: 68 | F32: 45 | G32: 900 | I32: 0 | J32: Ước tính/mô phỏng | K32: Sessions từ GA4; Clicks/Impressions từ Search Console.
A33: 46306 | B33: Paid | C33: TV3 – Anh Khoa / TV2 – Phương Thúy | D33: GA4 + Google Ads | E33: 50 | F33: 66 | G33: 2270 | I33: 198000 | J33: Ước tính/mô phỏng | K33: Sessions khác Clicks; không cộng hai chỉ số với nhau.
A34: 46306 | B34: Social Organic | C34: TV4 – Minh Thảo | D34: GA4 + Meta Insights | E34: 23 | F34: 31 | G34: 1550 | H34: 1110 | I34: 0 | J34: Ước tính/mô phỏng | K34: Social Traffic không trả phí; Reach/Impressions từ mạng xã hội.
A35: 46307 | B35: Organic | C35: TV3 – Anh Khoa | D35: GA4 + Search Console | E35: 64 | F35: 42 | G35: 875 | I35: 0 | J35: Ước tính/mô phỏng | K35: Sessions từ GA4; Clicks/Impressions từ Search Console.
A36: 46307 | B36: Paid | C36: TV3 – Anh Khoa / TV2 – Phương Thúy | D36: GA4 + Google Ads | E36: 47 | F36: 62 | G36: 2200 | I36: 186000 | J36: Ước tính/mô phỏng | K36: Sessions khác Clicks; không cộng hai chỉ số với nhau.
A37: 46307 | B37: Social Organic | C37: TV4 – Minh Thảo | D37: GA4 + Meta Insights | E37: 21 | F37: 28 | G37: 1500 | H37: 1080 | I37: 0 | J37: Ước tính/mô phỏng | K37: Social Traffic không trả phí; Reach/Impressions từ mạng xã hội.
A38: 46308 | B38: Organic | C38: TV3 – Anh Khoa | D38: GA4 + Search Console | E38: 71 | F38: 47 | G38: 940 | I38: 0 | J38: Ước tính/mô phỏng | K38: Sessions từ GA4; Clicks/Impressions từ Search Console.
A39: 46308 | B39: Paid | C39: TV3 – Anh Khoa / TV2 – Phương Thúy | D39: GA4 + Google Ads | E39: 53 | F39: 69 | G39: 2390 | I39: 207000 | J39: Ước tính/mô phỏng | K39: Sessions khác Clicks; không cộng hai chỉ số với nhau.
A40: 46308 | B40: Social Organic | C40: TV4 – Minh Thảo | D40: GA4 + Meta Insights | E40: 24 | F40: 32 | G40: 1640 | H40: 1170 | I40: 0 | J40: Ước tính/mô phỏng | K40: Social Traffic không trả phí; Reach/Impressions từ mạng xã hội.
...

Sheet Lich_Social_14N
A1: Ngày | B1: Mã nội dung | C1: Kênh | D1: Nội dung | E1: Trụ cột/phễu | F1: CTA | G1: Trạng thái
A2: 1 | B2: FP-01 | C2: Fanpage | D2: Giới thiệu SOVA, ba dung tích | E2: Awareness | F2: Nhắn tin tư vấn | G2: Kế hoạch – chưa đăng
A3: 2 | B3: TT-01 | C3: TikTok | D3: Ba dung tích – bạn hợp bình nào? | E3: Chọn dung tích | F3: Link ở bio | G3: Kịch bản có sẵn theo GĐ4; xác minh
A4: 3 | B4: FP-02 | C4: Fanpage | D4: Hỏi người xem đang dùng bình bao nhiêu ml | E4: Awareness | F4: Bình luận dung tích | G4: Kế hoạch – chưa đăng
A5: 4 | B5: TT-02 | C5: TikTok | D5: Test bình thực tế | E5: Test sản phẩm | F5: Link ở bio | G5: Chỉ đăng sau khi tự đo
A6: 5 | B6: FP-03 | C6: Fanpage | D6: Infographic so sánh 500/750/1000 ml và giá | E6: Consideration | F6: Nhắn tin nhận tư vấn | G6: Giá cần đối chiếu SKU
A7: 6 | B7: TT-03 | C7: TikTok | D7: Mẹo vệ sinh bình, giới thiệu cọ | E7: Hữu ích/bán kèm | F7: Xem combo ở bio | G7: Kịch bản có sẵn theo GĐ4
A8: 8 | B8: FP-04 | C8: Fanpage | D8: Combo bình + túi + cọ, nêu mức tiết kiệm | E8: Consideration | F8: Xem combo tại Landing Page | G8: Chưa đăng; chốt giá combo
A9: 9 | B9: TT-04 | C9: TikTok | D9: Lifestyle: trong túi mình có gì? | E9: Lifestyle | F9: Link ở bio | G9: Cần viết kịch bản
A10: 10 | B10: FP-05 | C10: Fanpage | D10: Hướng dẫn vệ sinh bình 3 bước | E10: Consideration | F10: Lưu bài | G10: Kế hoạch – chưa đăng
A11: 11 | B11: TT-05 | C11: TikTok | D11: So sánh trung thực với bình/ly phổ thông | E11: So sánh | F11: Link ở bio | G11: Cần viết kịch bản
A12: 12 | B12: FP-06 | C12: Fanpage | D12: Ảnh thật các màu và tình trạng còn hàng | E12: Conversion | F12: Nhắn tin đặt hàng | G12: Chỉ đăng khi xác nhận tồn kho
A13: 13 | B13: TT-06 | C13: TikTok | D13: Mùa lạnh/quà tặng và combo | E13: Seasonal | F13: Xem combo ở bio | G13: Cần viết kịch bản
A14: 14 | B14: FP-07 | C14: Fanpage | D14: Chia sẻ video KOC khi được đồng ý | E14: Social proof | F14: Xem video TikTok | G14: Chỉ khi KOC đồng ý

Sheet Risk_Pivot
A1: Rủi ro/tình huống | B1: KPI theo dõi | C1: Ngưỡng phát hiện | D1: Nguyên nhân giả định | E1: Quyết định Pivot | F1: Kết quả kỳ vọng | G1: Trạng thái
A2: CAC tăng do đối thủ cạnh tranh giá thầu | B2: CAC | C2: Tăng ≥20% so với CAC nền GĐ3 | D2: CPC tăng hoặc chuyển đổi Landing Page giảm | E2: Tạm dừng từ khóa CPC cao, phân bổ ngân sách sang long-tail; kiểm tra lại Landing Page và thông điệp | F2: Giảm CAC về gần ngưỡng nền; bảo toàn ngân sách | G2: Tình huống giả định theo đề, chưa phát sinh thực tế
A3: Impressions cao nhưng CTR thấp | B3: CTR, clicks | C3: CTR giảm liên tiếp 3 ngày so với mức nền | D3: Thông điệp chưa khớp ý định/từ khóa | E3: Thử RSA theo nhóm ý định; rà soát từ khóa phủ định và CTA | F3: Tăng chất lượng nhấp | G3: Cần theo dõi khi có dữ liệu thật
A4: Traffic tăng nhưng không có đơn | B4: CVR, CAC, đơn hàng | C4: Có sessions/clicks nhưng không ghi nhận đơn | D4: Landing Page, giá, CTA hoặc quy trình đặt hàng có vấn đề | E4: Kiểm tra tốc độ/mobile, giá và CTA; đo sự kiện chuyển đổi | F4: Cải thiện tỷ lệ chuyển đổi | G4: Cần dữ liệu GA4/đơn hàng
A5: KOC đăng nhưng không có link clicks | B5: Link clicks, sessions theo UTM | C5: Sau 48–72 giờ không có click đo được | D5: CTA/link/mã chưa rõ hoặc nội dung không phù hợp | E5: Tối ưu CTA, ghim link/mã, dùng nội dung tốt nhất để boost khi có quyền | F5: Tăng traffic có thể quy nguồn | G5: Kế hoạch quản trị

Sheet Traffic_Ngay
A1: Ngày | B1: Organic Sessions | C1: Paid Sessions | D1: Social Sessions | E1: Paid Spend | F1: Organic Impressions | G1: Paid Impressions | H1: Social Reach | I1: Social Impressions
A2: 46296 | B2: =SUMIFS(Traffic_Mo_phong!$E$2:$E$1000,Traffic_Mo_phong!$A$2:$A$1000,$A2,Traffic_Mo_phong!$B$2:$B$1000,"Organic") -> 42 | C2: =SUMIFS(Traffic_Mo_phong!$E$2:$E$1000,Traffic_Mo_phong!$A$2:$A$1000,$A2,Traffic_Mo_phong!$B$2:$B$1000,"Paid") -> 31 | D2: =SUMIFS(Traffic_Mo_phong!$E$2:$E$1000,Traffic_Mo_phong!$A$2:$A$1000,$A2,Traffic_Mo_phong!$B$2:$B$1000,"Social Organic") -> 12 | E2: =SUMIFS(Traffic_Mo_phong!$I$2:$I$1000,Traffic_Mo_phong!$A$2:$A$1000,$A2,Traffic_Mo_phong!$B$2:$B$1000,"Paid") -> 126000 | F2: =SUMIFS(Traffic_Mo_phong!$G$2:$G$1000,Traffic_Mo_phong!$A$2:$A$1000,$A2,Traffic_Mo_phong!$B$2:$B$1000,"Organic") -> 610 | G2: =SUMIFS(Traffic_Mo_phong!$G$2:$G$1000,Traffic_Mo_phong!$A$2:$A$1000,$A2,Traffic_Mo_phong!$B$2:$B$1000,"Paid") -> 1500 | H2: =SUMIFS(Traffic_Mo_phong!$H$2:$H$1000,Traffic_Mo_phong!$A$2:$A$1000,$A2,Traffic_Mo_phong!$B$2:$B$1000,"Social Organic") -> 720 | I2: =SUMIFS(Traffic_Mo_phong!$G$2:$G$1000,Traffic_Mo_phong!$A$2:$A$1000,$A2,Traffic_Mo_phong!$B$2:$B$1000,"Social Organic") -> 980
A3: 46297 | B3: =SUMIFS(Traffic_Mo_phong!$E$2:$E$1000,Traffic_Mo_phong!$A$2:$A$1000,$A3,Traffic_Mo_phong!$B$2:$B$1000,"Organic") -> 48 | C3: =SUMIFS(Traffic_Mo_phong!$E$2:$E$1000,Traffic_Mo_phong!$A$2:$A$1000,$A3,Traffic_Mo_phong!$B$2:$B$1000,"Paid") -> 35 | D3: =SUMIFS(Traffic_Mo_phong!$E$2:$E$1000,Traffic_Mo_phong!$A$2:$A$1000,$A3,Traffic_Mo_phong!$B$2:$B$1000,"Social Organic") -> 14 | E3: =SUMIFS(Traffic_Mo_phong!$I$2:$I$1000,Traffic_Mo_phong!$A$2:$A$1000,$A3,Traffic_Mo_phong!$B$2:$B$1000,"Paid") -> 138000 | F3: =SUMIFS(Traffic_Mo_phong!$G$2:$G$1000,Traffic_Mo_phong!$A$2:$A$1000,$A3,Traffic_Mo_phong!$B$2:$B$1000,"Organic") -> 650 | G3: =SUMIFS(Traffic_Mo_phong!$G$2:$G$1000,Traffic_Mo_phong!$A$2:$A$1000,$A3,Traffic_Mo_phong!$B$2:$B$1000,"Paid") -> 1620 | H3: =SUMIFS(Traffic_Mo_phong!$H$2:$H$1000,Traffic_Mo_phong!$A$2:$A$1000,$A3,Traffic_Mo_phong!$B$2:$B$1000,"Social Organic") -> 770 | I3: =SUMIFS(Traffic_Mo_phong!$G$2:$G$1000,Traffic_Mo_phong!$A$2:$A$1000,$A3,Traffic_Mo_phong!$B$2:$B$1000,"Social Organic") -> 1050
A4: 46298 | B4: =SUMIFS(Traffic_Mo_phong!$E$2:$E$1000,Traffic_Mo_phong!$A$2:$A$1000,$A4,Traffic_Mo_phong!$B$2:$B$1000,"Organic") -> 45 | C4: =SUMIFS(Traffic_Mo_phong!$E$2:$E$1000,Traffic_Mo_phong!$A$2:$A$1000,$A4,Traffic_Mo_phong!$B$2:$B$1000,"Paid") -> 33 | D4: =SUMIFS(Traffic_Mo_phong!$E$2:$E$1000,Traffic_Mo_phong!$A$2:$A$1000,$A4,Traffic_Mo_phong!$B$2:$B$1000,"Social Organic") -> 13 | E4: =SUMIFS(Traffic_Mo_phong!$I$2:$I$1000,Traffic_Mo_phong!$A$2:$A$1000,$A4,Traffic_Mo_phong!$B$2:$B$1000,"Paid") -> 132000 | F4: =SUMIFS(Traffic_Mo_phong!$G$2:$G$1000,Traffic_Mo_phong!$A$2:$A$1000,$A4,Traffic_Mo_phong!$B$2:$B$1000,"Organic") -> 630 | G4: =SUMIFS(Traffic_Mo_phong!$G$2:$G$1000,Traffic_Mo_phong!$A$2:$A$1000,$A4,Traffic_Mo_phong!$B$2:$B$1000,"Paid") -> 1580 | H4: =SUMIFS(Traffic_Mo_phong!$H$2:$H$1000,Traffic_Mo_phong!$A$2:$A$1000,$A4,Traffic_Mo_phong!$B$2:$B$1000,"Social Organic") -> 745 | I4: =SUMIFS(Traffic_Mo_phong!$G$2:$G$1000,Traffic_Mo_phong!$A$2:$A$1000,$A4,Traffic_Mo_phong!$B$2:$B$1000,"Social Organic") -> 1010
A5: 46299 | B5: =SUMIFS(Traffic_Mo_phong!$E$2:$E$1000,Traffic_Mo_phong!$A$2:$A$1000,$A5,Traffic_Mo_phong!$B$2:$B$1000,"Organic") -> 53 | C5: =SUMIFS(Traffic_Mo_phong!$E$2:$E$1000,Traffic_Mo_phong!$A$2:$A$1000,$A5,Traffic_Mo_phong!$B$2:$B$1000,"Paid") -> 38 | D5: =SUMIFS(Traffic_Mo_phong!$E$2:$E$1000,Traffic_Mo_phong!$A$2:$A$1000,$A5,Traffic_Mo_phong!$B$2:$B$1000,"Social Organic") -> 16 | E5: =SUMIFS(Traffic_Mo_phong!$I$2:$I$1000,Traffic_Mo_phong!$A$2:$A$1000,$A5,Traffic_Mo_phong!$B$2:$B$1000,"Paid") -> 150000 | F5: =SUMIFS(Traffic_Mo_phong!$G$2:$G$1000,Traffic_Mo_phong!$A$2:$A$1000,$A5,Traffic_Mo_phong!$B$2:$B$1000,"Organic") -> 700 | G5: =SUMIFS(Traffic_Mo_phong!$G$2:$G$1000,Traffic_Mo_phong!$A$2:$A$1000,$A5,Traffic_Mo_phong!$B$2:$B$1000,"Paid") -> 1750 | H5: =SUMIFS(Traffic_Mo_phong!$H$2:$H$1000,Traffic_Mo_phong!$A$2:$A$1000,$A5,Traffic_Mo_phong!$B$2:$B$1000,"Social Organic") -> 830 | I5: =SUMIFS(Traffic_Mo_phong!$G$2:$G$1000,Traffic_Mo_phong!$A$2:$A$1000,$A5,Traffic_Mo_phong!$B$2:$B$1000,"Social Organic") -> 1140
A6: 46300 | B6: =SUMIFS(Traffic_Mo_phong!$E$2:$E$1000,Traffic_Mo_phong!$A$2:$A$1000,$A6,Traffic_Mo_phong!$B$2:$B$1000,"Organic") -> 57 | C6: =SUMIFS(Traffic_Mo_phong!$E$2:$E$1000,Traffic_Mo_phong!$A$2:$A$1000,$A6,Traffic_Mo_phong!$B$2:$B$1000,"Paid") -> 42 | D6: =SUMIFS(Traffic_Mo_phong!$E$2:$E$1000,Traffic_Mo_phong!$A$2:$A$1000,$A6,Traffic_Mo_phong!$B$2:$B$1000,"Social Organic") -> 18 | E6: =SUMIFS(Traffic_Mo_phong!$I$2:$I$1000,Traffic_Mo_phong!$A$2:$A$1000,$A6,Traffic_Mo_phong!$B$2:$B$1000,"Paid") -> 165000 | F6: =SUMIFS(Traffic_Mo_phong!$G$2:$G$1000,Traffic_Mo_phong!$A$2:$A$1000,$A6,Traffic_Mo_phong!$B$2:$B$1000,"Organic") -> 740 | G6: =SUMIFS(Traffic_Mo_phong!$G$2:$G$1000,Traffic_Mo_phong!$A$2:$A$1000,$A6,Traffic_Mo_phong!$B$2:$B$1000,"Paid") -> 1880 | H6: =SUMIFS(Traffic_Mo_phong!$H$2:$H$1000,Traffic_Mo_phong!$A$2:$A$1000,$A6,Traffic_Mo_phong!$B$2:$B$1000,"Social Organic") -> 890 | I6: =SUMIFS(Traffic_Mo_phong!$G$2:$G$1000,Traffic_Mo_phong!$A$2:$A$1000,$A6,Traffic_Mo_phong!$B$2:$B$1000,"Social Organic") -> 1240
A7: 46301 | B7: =SUMIFS(Traffic_Mo_phong!$E$2:$E$1000,Traffic_Mo_phong!$A$2:$A$1000,$A7,Traffic_Mo_phong!$B$2:$B$1000,"Organic") -> 51 | C7: =SUMIFS(Traffic_Mo_phong!$E$2:$E$1000,Traffic_Mo_phong!$A$2:$A$1000,$A7,Traffic_Mo_phong!$B$2:$B$1000,"Paid") -> 37 | D7: =SUMIFS(Traffic_Mo_phong!$E$2:$E$1000,Traffic_Mo_phong!$A$2:$A$1000,$A7,Traffic_Mo_phong!$B$2:$B$1000,"Social Organic") -> 15 | E7: =SUMIFS(Traffic_Mo_phong!$I$2:$I$1000,Traffic_Mo_phong!$A$2:$A$1000,$A7,Traffic_Mo_phong!$B$2:$B$1000,"Paid") -> 147000 | F7: =SUMIFS(Traffic_Mo_phong!$G$2:$G$1000,Traffic_Mo_phong!$A$2:$A$1000,$A7,Traffic_Mo_phong!$B$2:$B$1000,"Organic") -> 715 | G7: =SUMIFS(Traffic_Mo_phong!$G$2:$G$1000,Traffic_Mo_phong!$A$2:$A$1000,$A7,Traffic_Mo_phong!$B$2:$B$1000,"Paid") -> 1810 | H7: =SUMIFS(Traffic_Mo_phong!$H$2:$H$1000,Traffic_Mo_phong!$A$2:$A$1000,$A7,Traffic_Mo_phong!$B$2:$B$1000,"Social Organic") -> 850 | I7: =SUMIFS(Traffic_Mo_phong!$G$2:$G$1000,Traffic_Mo_phong!$A$2:$A$1000,$A7,Traffic_Mo_phong!$B$2:$B$1000,"Social Organic") -> 1180
A8: 46302 | B8: =SUMIFS(Traffic_Mo_phong!$E$2:$E$1000,Traffic_Mo_phong!$A$2:$A$1000,$A8,Traffic_Mo_phong!$B$2:$B$1000,"Organic") -> 60 | C8: =SUMIFS(Traffic_Mo_phong!$E$2:$E$1000,Traffic_Mo_phong!$A$2:$A$1000,$A8,Traffic_Mo_phong!$B$2:$B$1000,"Paid") -> 44 | D8: =SUMIFS(Traffic_Mo_phong!$E$2:$E$1000,Traffic_Mo_phong!$A$2:$A$1000,$A8,Traffic_Mo_phong!$B$2:$B$1000,"Social Organic") -> 19 | E8: =SUMIFS(Traffic_Mo_phong!$I$2:$I$1000,Traffic_Mo_phong!$A$2:$A$1000,$A8,Traffic_Mo_phong!$B$2:$B$1000,"Paid") -> 174000 | F8: =SUMIFS(Traffic_Mo_phong!$G$2:$G$1000,Traffic_Mo_phong!$A$2:$A$1000,$A8,Traffic_Mo_phong!$B$2:$B$1000,"Organic") -> 780 | G8: =SUMIFS(Traffic_Mo_phong!$G$2:$G$1000,Traffic_Mo_phong!$A$2:$A$1000,$A8,Traffic_Mo_phong!$B$2:$B$1000,"Paid") -> 1990 | H8: =SUMIFS(Traffic_Mo_phong!$H$2:$H$1000,Traffic_Mo_phong!$A$2:$A$1000,$A8,Traffic_Mo_phong!$B$2:$B$1000,"Social Organic") -> 930 | I8: =SUMIFS(Traffic_Mo_phong!$G$2:$G$1000,Traffic_Mo_phong!$A$2:$A$1000,$A8,Traffic_Mo_phong!$B$2:$B$1000,"Social Organic") -> 1300
A9: 46303 | B9: =SUMIFS(Traffic_Mo_phong!$E$2:$E$1000,Traffic_Mo_phong!$A$2:$A$1000,$A9,Traffic_Mo_phong!$B$2:$B$1000,"Organic") -> 62 | C9: =SUMIFS(Traffic_Mo_phong!$E$2:$E$1000,Traffic_Mo_phong!$A$2:$A$1000,$A9,Traffic_Mo_phong!$B$2:$B$1000,"Paid") -> 46 | D9: =SUMIFS(Traffic_Mo_phong!$E$2:$E$1000,Traffic_Mo_phong!$A$2:$A$1000,$A9,Traffic_Mo_phong!$B$2:$B$1000,"Social Organic") -> 20 | E9: =SUMIFS(Traffic_Mo_phong!$I$2:$I$1000,Traffic_Mo_phong!$A$2:$A$1000,$A9,Traffic_Mo_phong!$B$2:$B$1000,"Paid") -> 180000 | F9: =SUMIFS(Traffic_Mo_phong!$G$2:$G$1000,Traffic_Mo_phong!$A$2:$A$1000,$A9,Traffic_Mo_phong!$B$2:$B$1000,"Organic") -> 810 | G9: =SUMIFS(Traffic_Mo_phong!$G$2:$G$1000,Traffic_Mo_phong!$A$2:$A$1000,$A9,Traffic_Mo_phong!$B$2:$B$1000,"Paid") -> 2050 | H9: =SUMIFS(Traffic_Mo_phong!$H$2:$H$1000,Traffic_Mo_phong!$A$2:$A$1000,$A9,Traffic_Mo_phong!$B$2:$B$1000,"Social Organic") -> 990 | I9: =SUMIFS(Traffic_Mo_phong!$G$2:$G$1000,Traffic_Mo_phong!$A$2:$A$1000,$A9,Traffic_Mo_phong!$B$2:$B$1000,"Social Organic") -> 1380
A10: 46304 | B10: =SUMIFS(Traffic_Mo_phong!$E$2:$E$1000,Traffic_Mo_phong!$A$2:$A$1000,$A10,Traffic_Mo_phong!$B$2:$B$1000,"Organic") -> 58 | C10: =SUMIFS(Traffic_Mo_phong!$E$2:$E$1000,Traffic_Mo_phong!$A$2:$A$1000,$A10,Traffic_Mo_phong!$B$2:$B$1000,"Paid") -> 43 | D10: =SUMIFS(Traffic_Mo_phong!$E$2:$E$1000,Traffic_Mo_phong!$A$2:$A$1000,$A10,Traffic_Mo_phong!$B$2:$B$1000,"Social Organic") -> 18 | E10: =SUMIFS(Traffic_Mo_phong!$I$2:$I$1000,Traffic_Mo_phong!$A$2:$A$1000,$A10,Traffic_Mo_phong!$B$2:$B$1000,"Paid") -> 171000 | F10: =SUMIFS(Traffic_Mo_phong!$G$2:$G$1000,Traffic_Mo_phong!$A$2:$A$1000,$A10,Traffic_Mo_phong!$B$2:$B$1000,"Organic") -> 790 | G10: =SUMIFS(Traffic_Mo_phong!$G$2:$G$1000,Traffic_Mo_phong!$A$2:$A$1000,$A10,Traffic_Mo_phong!$B$2:$B$1000,"Paid") -> 2010 | H10: =SUMIFS(Traffic_Mo_phong!$H$2:$H$1000,Traffic_Mo_phong!$A$2:$A$1000,$A10,Traffic_Mo_phong!$B$2:$B$1000,"Social Organic") -> 950 | I10: =SUMIFS(Traffic_Mo_phong!$G$2:$G$1000,Traffic_Mo_phong!$A$2:$A$1000,$A10,Traffic_Mo_phong!$B$2:$B$1000,"Social Organic") -> 1330
A11: 46305 | B11: =SUMIFS(Traffic_Mo_phong!$E$2:$E$1000,Traffic_Mo_phong!$A$2:$A$1000,$A11,Traffic_Mo_phong!$B$2:$B$1000,"Organic") -> 65 | C11: =SUMIFS(Traffic_Mo_phong!$E$2:$E$1000,Traffic_Mo_phong!$A$2:$A$1000,$A11,Traffic_Mo_phong!$B$2:$B$1000,"Paid") -> 48 | D11: =SUMIFS(Traffic_Mo_phong!$E$2:$E$1000,Traffic_Mo_phong!$A$2:$A$1000,$A11,Traffic_Mo_phong!$B$2:$B$1000,"Social Organic") -> 22 | E11: =SUMIFS(Traffic_Mo_phong!$I$2:$I$1000,Traffic_Mo_phong!$A$2:$A$1000,$A11,Traffic_Mo_phong!$B$2:$B$1000,"Paid") -> 189000 | F11: =SUMIFS(Traffic_Mo_phong!$G$2:$G$1000,Traffic_Mo_phong!$A$2:$A$1000,$A11,Traffic_Mo_phong!$B$2:$B$1000,"Organic") -> 860 | G11: =SUMIFS(Traffic_Mo_phong!$G$2:$G$1000,Traffic_Mo_phong!$A$2:$A$1000,$A11,Traffic_Mo_phong!$B$2:$B$1000,"Paid") -> 2180 | H11: =SUMIFS(Traffic_Mo_phong!$H$2:$H$1000,Traffic_Mo_phong!$A$2:$A$1000,$A11,Traffic_Mo_phong!$B$2:$B$1000,"Social Organic") -> 1050 | I11: =SUMIFS(Traffic_Mo_phong!$G$2:$G$1000,Traffic_Mo_phong!$A$2:$A$1000,$A11,Traffic_Mo_phong!$B$2:$B$1000,"Social Organic") -> 1480
A12: 46306 | B12: =SUMIFS(Traffic_Mo_phong!$E$2:$E$1000,Traffic_Mo_phong!$A$2:$A$1000,$A12,Traffic_Mo_phong!$B$2:$B$1000,"Organic") -> 68 | C12: =SUMIFS(Traffic_Mo_phong!$E$2:$E$1000,Traffic_Mo_phong!$A$2:$A$1000,$A12,Traffic_Mo_phong!$B$2:$B$1000,"Paid") -> 50 | D12: =SUMIFS(Traffic_Mo_phong!$E$2:$E$1000,Traffic_Mo_phong!$A$2:$A$1000,$A12,Traffic_Mo_phong!$B$2:$B$1000,"Social Organic") -> 23 | E12: =SUMIFS(Traffic_Mo_phong!$I$2:$I$1000,Traffic_Mo_phong!$A$2:$A$1000,$A12,Traffic_Mo_phong!$B$2:$B$1000,"Paid") -> 198000 | F12: =SUMIFS(Traffic_Mo_phong!$G$2:$G$1000,Traffic_Mo_phong!$A$2:$A$1000,$A12,Traffic_Mo_phong!$B$2:$B$1000,"Organic") -> 900 | G12: =SUMIFS(Traffic_Mo_phong!$G$2:$G$1000,Traffic_Mo_phong!$A$2:$A$1000,$A12,Traffic_Mo_phong!$B$2:$B$1000,"Paid") -> 2270 | H12: =SUMIFS(Traffic_Mo_phong!$H$2:$H$1000,Traffic_Mo_phong!$A$2:$A$1000,$A12,Traffic_Mo_phong!$B$2:$B$1000,"Social Organic") -> 1110 | I12: =SUMIFS(Traffic_Mo_phong!$G$2:$G$1000,Traffic_Mo_phong!$A$2:$A$1000,$A12,Traffic_Mo_phong!$B$2:$B$1000,"Social Organic") -> 1550
A13: 46307 | B13: =SUMIFS(Traffic_Mo_phong!$E$2:$E$1000,Traffic_Mo_phong!$A$2:$A$1000,$A13,Traffic_Mo_phong!$B$2:$B$1000,"Organic") -> 64 | C13: =SUMIFS(Traffic_Mo_phong!$E$2:$E$1000,Traffic_Mo_phong!$A$2:$A$1000,$A13,Traffic_Mo_phong!$B$2:$B$1000,"Paid") -> 47 | D13: =SUMIFS(Traffic_Mo_phong!$E$2:$E$1000,Traffic_Mo_phong!$A$2:$A$1000,$A13,Traffic_Mo_phong!$B$2:$B$1000,"Social Organic") -> 21 | E13: =SUMIFS(Traffic_Mo_phong!$I$2:$I$1000,Traffic_Mo_phong!$A$2:$A$1000,$A13,Traffic_Mo_phong!$B$2:$B$1000,"Paid") -> 186000 | F13: =SUMIFS(Traffic_Mo_phong!$G$2:$G$1000,Traffic_Mo_phong!$A$2:$A$1000,$A13,Traffic_Mo_phong!$B$2:$B$1000,"Organic") -> 875 | G13: =SUMIFS(Traffic_Mo_phong!$G$2:$G$1000,Traffic_Mo_phong!$A$2:$A$1000,$A13,Traffic_Mo_phong!$B$2:$B$1000,"Paid") -> 2200 | H13: =SUMIFS(Traffic_Mo_phong!$H$2:$H$1000,Traffic_Mo_phong!$A$2:$A$1000,$A13,Traffic_Mo_phong!$B$2:$B$1000,"Social Organic") -> 1080 | I13: =SUMIFS(Traffic_Mo_phong!$G$2:$G$1000,Traffic_Mo_phong!$A$2:$A$1000,$A13,Traffic_Mo_phong!$B$2:$B$1000,"Social Organic") -> 1500
... A15: 46309 | B15: =SUMIFS(Traffic_Mo_phong!$E$2:$E$1000,Traffic_Mo_phong!$A$2:$A$1000,$A15,Traffic_Mo_phong!$B$2:$B$1000,"Organic") -> 75 | C15: =SUMIFS(Traffic_Mo_phong!$E$2:$E$1000,Traffic_Mo_phong!$A$2:$A$1000,$A15,Traffic_Mo_phong!$B$2:$B$1000,"Paid") -> 56 | D15: =SUMIFS(Traffic_Mo_phong!$E$2:$E$1000,Traffic_Mo_phong!$A$2:$A$1000,$A15,Traffic_Mo_phong!$B$2:$B$1000,"Social Organic") -> 27 | E15: =SUMIFS(Traffic_Mo_phong!$I$2:$I$1000,Traffic_Mo_phong!$A$2:$A$1000,$A15,Traffic_Mo_phong!$B$2:$B$1000,"Paid") -> 219000 | F15: =SUMIFS(Traffic_Mo_phong!$G$2:$G$1000,Traffic_Mo_phong!$A$2:$A$1000,$A15,Traffic_Mo_phong!$B$2:$B$1000,"Organic") -> 990 | G15: =SUMIFS(Traffic_Mo_phong!$G$2:$G$1000,Traffic_Mo_phong!$A$2:$A$1000,$A15,Traffic_Mo_phong!$B$2:$B$1000,"Paid") -> 2510 | H15: =SUMIFS(Traffic_Mo_phong!$H$2:$H$1000,Traffic_Mo_phong!$A$2:$A$1000,$A15,Traffic_Mo_phong!$B$2:$B$1000,"Social Organic") -> 1280 | I15: =SUMIFS(Traffic_Mo_phong!$G$2:$G$1000,Traffic_Mo_phong!$A$2:$A$1000,$A15,Traffic_Mo_phong!$B$2:$B$1000,"Social Organic") -> 1780

Sheet SEM CẤU HÌNH
A1: CẤU HÌNH SEM – TV2 PHƯƠNG THÚY | B1: Giá trị / trạng thái | C1: Nguồn / ghi chú
A2: Thành viên phụ trách | B2: TV2 – Phương Thúy | C2: Theo phân công Giai đoạn 5
A3: Chiến dịch đề xuất | B3: SOVA – Search – Bình giữ nhiệt | C3: Chiến dịch Google Search Ads
A4: Loại chiến dịch | B4: Tìm kiếm (Search) | C4: Phù hợp truy vấn có ý định mua
A5: Mục tiêu | B5: Lưu lượng truy cập; chỉ chọn Doanh số nếu đã thiết lập theo dõi chuyển đổi | C5: Không tuyên bố có chuyển đổi nếu chưa xác minh tracking
A6: URL Landing Page | B6: https://sova.liveblog365.com | C6: URL đã được dùng trong tài liệu dự án; TV3 – Anh Khoa cần xác nhận URL chính thức/hoạt động
A7: Vị trí | B7: Việt Nam (đề xuất) | C7: Ảnh hiện trạng trước đó có thể chọn phạm vi khác; cần kiểm tra lại giao diện
A8: Ngôn ngữ | B8: Tiếng Việt (đề xuất) | C8: Khớp nội dung quảng cáo
A9: Chiến lược giá thầu | B9: Tối đa hóa lượt nhấp (Maximize Clicks) – phương án mô phỏng | C9: Phù hợp khi mục tiêu là traffic; cần xem lại khi có tracking chuyển đổi
A10: CPC tối đa tham khảo | B10: Không đặt vượt quá khoảng 11.000đ/nhấp nếu không có căn cứ | C10: Dải giá thầu cao đầu trang trong nhóm từ khóa dao động; không phải CPC thực tế
A11: Ngân sách Google Ads/tháng theo GĐ3 | B11: CHƯA CÓ DỮ LIỆU trong sheet GD3_Dau_vao | C11: Không được tự suy ra là 15.000.000đ/tháng
A12: Ngân sách trung bình/ngày | B12: CHƯA XÁC NHẬN | C12: 500.000đ/ngày chỉ được dùng trong một số ảnh mô phỏng; cần nhóm xác nhận ngân sách tháng ở GĐ3 trước khi xem là chính thức
... A22: Ghi chú bàn giao | B22: Bàn giao cho TV1 – Phương Kiều | C22: Chỉ bàn giao dữ liệu thực tế khi có nguồn; hiện tại bàn giao kế hoạch/preview và trạng thái thiếu dữ liệu

Sheet SEM KỊCH BẢN PHÂN TÍCH
A1: KỊCH BẢN PHÂN TÍCH KPI SEM – SOVA
A2: Lưu ý | B2: Các giá trị dưới đây là kịch bản tính toán minh họa; thay bằng báo cáo Google Ads/analytics đã xác minh khi có dữ liệu.
A3: Chỉ số | B3: RSA A – Nhấn giá | C3: RSA B – Nhấn dịch vụ | D3: Công thức | E3: Đơn vị/ghi chú
A4: Impressions | B4: 10000 | C4: 10000 | D4: Nguồn nền tảng | E4: lượt hiển thị – giả định
A5: Clicks | B5: 400 | C5: 350 | D5: Nguồn nền tảng | E5: lượt nhấp – giả định
A6: CTR | B6: =IFERROR(B5/B4,0) -> 0.04 | C6: =IFERROR(C5/C4,0) -> 0.035 | D6: Clicks / Impressions | E6: tỷ lệ
A7: Chi phí | B7: 3200000 | C7: 2975000 | D7: Nguồn nền tảng | E7: VND – giả định
A8: CPC trung bình | B8: =IFERROR(B7/B5,0) -> 8000 | C8: =IFERROR(C7/C5,0) -> 8500 | D8: Chi phí / Clicks | E8: VND/nhấp
A9: Conversions | B9: 12 | C9: 14 | D9: Google Ads/analytics | E9: chuyển đổi – giả định
A10: CVR | B10: =IFERROR(B9/B5,0) -> 0.03 | C10: =IFERROR(C9/C5,0) -> 0.04 | D10: Conversions / Clicks | E10: tỷ lệ
A11: CPA | B11: =IFERROR(B7/B9,0) -> 266666.67 | C11: =IFERROR(C7/C9,0) -> 212500 | D11: Chi phí / Conversions | E11: VND/chuyển đổi
A12: Giá trị đơn hàng TB | B12: 229000 | C12: 229000 | D12: Giá trị AOV minh họa | E12: VND/đơn
A13: Doanh thu | B13: =B9*B12 -> 2748000 | C13: =C9*C12 -> 3206000 | D13: Conversions × AOV | E13: VND – giả định
A14: ROAS | B14: =IFERROR(B13/B7,0) -> 0.85875 | C14: =IFERROR(C13/C7,0) -> 1.0776471 | D14: Doanh thu / Chi phí | E14: lần
A15: Ngân sách ngày tham khảo | B15: 200000 | C15: 200000 | D15: Ngân sách minh họa | E15: VND/ngày; cần đối chiếu ngân sách được duyệt
A16: Ngân sách 30 ngày | B16: =B15*30 -> 6000000 | C16: =C15*30 -> 6000000 | D16: Ngân sách ngày × 30 | E16: VND

Sheet SEM TỪ ĐIỂN DỮ LIỆU
A1: TỪ ĐIỂN DỮ LIỆU SEM
A2: Trường | B2: Định nghĩa/công thức | C2: Nguồn và quy tắc
A3: Impressions | B3: Số lần quảng cáo được hiển thị | C3: Google Ads; không điền từ Preview
A4: Clicks | B4: Số lượt nhấp quảng cáo | C4: Google Ads
A5: CTR | B5: Clicks / Impressions | C5: Tính từ số liệu cùng phạm vi ngày
A6: Chi phí | B6: Tổng chi phí quảng cáo trong phạm vi báo cáo | C6: Google Ads; VND
A7: CPC trung bình | B7: Chi phí / Clicks | C7: Nếu Clicks=0 thì để trống/NA
A8: Conversions | B8: Số chuyển đổi được ghi nhận | C8: Chỉ dùng khi conversion action/tracking đã xác minh
A9: CVR | B9: Conversions / Clicks | C9: Cùng attribution window và cùng phạm vi
A10: CPA | B10: Chi phí / Conversions | C10: Nếu conversions=0 thì không chia cho 0
A11: Doanh thu | B11: Giá trị chuyển đổi mua hàng được ghi nhận | C11: Không suy ra từ clicks; kiểm tra trùng attribution
A12: ROAS | B12: Doanh thu / Chi phí | C12: Chỉ tính khi có doanh thu và chi phí cùng phạm vi
A13: Ngày tải dữ liệu | B13: Ngày xuất báo cáo từ nền tảng | C13: Ghi lại để có thể truy xuất/đối chiếu
